Workbook

Sheet 部集計
A1: ２９年度ビル管理部人件費予算内訳
C2: ４月 | D2: ５月 | E2: ６月 | F2: ７月 | G2: ８月 | H2: ９月 | I2: 上期 | J2: １０月 | K2: １１月 | L2: １２月 | M2: １月 | N2: ２月 | O2: ３月 | P2: 下期 | Q2: 合計
A3: 職員給与 | B3: 原価)業務課 | C3: =明細!O25 -> 2422893 | D3: =#REF! -> #REF! | E3: =#REF! -> #REF! | I3: =SUM(C3:H3) -> #REF! | P3: =SUM(J3:O3) -> 0 | Q3: =+I3+P3 -> #REF!
B4: マンション課 | C4: =明細!O31 -> 1372737 | I4: =SUM(C4:H4) -> 1372737 | P4: =SUM(J4:O4) -> 0 | Q4: =+I4+P4 -> 1372737
B5: 工事課 | C5: =明細!O41 -> 1835999 | I5: =SUM(C5:H5) -> 1835999 | P5: =SUM(J5:O5) -> 0 | Q5: =+I5+P5 -> 1835999
B6: 旭川営業所 | C6: =明細!O51 -> 947900 | I6: =SUM(C6:H6) -> 947900 | P6: =SUM(J6:O6) -> 0 | Q6: =+I6+P6 -> 947900
B7: 斎場管理課 | C7: =明細!O47 -> 1125600 | I7: =SUM(C7:H7) -> 1125600 | P7: =SUM(J7:O7) -> 0 | Q7: =+I7+P7 -> 1125600
B8: 保険課 | C8: =明細!O33 -> 198250 | I8: =SUM(C8:H8) -> 198250 | P8: =SUM(J8:O8) -> 0 | Q8: =+I8+P8 -> 198250
B9: 小計 | C9: =SUM(C3:C8) -> 7903379 | D9: =SUM(D3:D8) -> #REF! | E9: =SUM(E3:E8) -> #REF! | F9: =SUM(F3:F8) -> 0 | G9: =SUM(G3:G8) -> 0 | H9: =SUM(H3:H8) -> 0 | I9: =SUM(C9:H9) -> #REF! | J9: =SUM(J3:J8) -> 0 | K9: =SUM(K3:K8) -> 0 | L9: =SUM(L3:L8) -> 0 | M9: =SUM(M3:M8) -> 0 | N9: =SUM(N3:N8) -> 0 | O9: =SUM(O3:O8) -> 0 | P9: =SUM(P3:P8) -> 0 | Q9: =SUM(K9:P9) -> 0
B10: 営業費 | C10: =明細!O13 -> 2854481 | I10: =SUM(C10:H10) -> 2854481 | P10: =SUM(P4:P9) -> 0 | Q10: =SUM(K10:P10) -> 0
B11: 合計 | C11: =+C9+C10 -> 10757860 | D11: =+D9+D10 -> #REF! | E11: =+E9+E10 -> #REF! | F11: =+F9+F10 -> 0 | G11: =+G9+G10 -> 0 | H11: =+H9+H10 -> 0 | I11: =SUM(I10) -> 2854481 | J11: =+J9+J10 -> 0 | K11: =+K9+K10 -> 0 | L11: =+L9+L10 -> 0 | M11: =+M9+M10 -> 0 | N11: =+N9+N10 -> 0 | O11: =+O9+O10 -> 0 | P11: =SUM(P10) -> 0 | Q11: =SUM(Q10) -> 0
A12: 職員賞与 | B12: 業務課 | C12: =明細!P25 -> 488831 | I12: =SUM(C12:H12) -> 488831 | P12: =SUM(J12:O12) -> 0 | Q12: =+I12+P12 -> 488831
B13: マンション課 | C13: =明細!P31 -> 336164 | I13: =SUM(C13:H13) -> 336164 | P13: =SUM(J13:O13) -> 0 | Q13: =+I13+P13 -> 336164
B14: 工事課 | C14: =明細!P41 -> 393831 | I14: =SUM(C14:H14) -> 393831 | P14: =SUM(J14:O14) -> 0 | Q14: =+I14+P14 -> 393831
B15: 旭川営業所 | C15: =明細!P51 -> 211999 | I15: =SUM(C15:H15) -> 211999 | P15: =SUM(J15:O15) -> 0 | Q15: =+I15+P15 -> 211999
B16: 斎場管理課 | C16: =明細!P47 -> 216165 | I16: =SUM(C16:H16) -> 216165 | P16: =SUM(J16:O16) -> 0 | Q16: =+I16+P16 -> 216165
B17: 保険課 | C17: =明細!P33 -> 56250 | I17: =SUM(C17:H17) -> 56250 | P17: =SUM(J17:O17) -> 0 | Q17: =+I17+P17 -> 56250
B18: 小計 | C18: =SUM(C12:C17) -> 1703240 | D18: =SUM(D12:D17) -> 0 | E18: =SUM(E12:E17) -> 0 | F18: =SUM(F12:F17) -> 0 | G18: =SUM(G12:G17) -> 0 | H18: =SUM(H12:H17) -> 0 | I18: =SUM(C18:H18) -> 1703240 | J18: =SUM(J12:J17) -> 0 | K18: =SUM(K12:K17) -> 0 | L18: =SUM(L12:L17) -> 0 | M18: =SUM(M12:M17) -> 0 | N18: =SUM(N12:N17) -> 0 | O18: =SUM(O12:O17) -> 0 | P18: =SUM(P12:P17) -> 0 | Q18: =SUM(K18:P18) -> 0
B19: 営業費 | C19: =明細!P13 -> 799081 | I19: =SUM(C19:H19) -> 799081 | P19: =SUM(P13:P18) -> 0 | Q19: =SUM(K19:P19) -> 0
B20: 合計 | C20: =+C18+C19 -> 2502321 | D20: =+D18+D19 -> 0 | E20: =+E18+E19 -> 0 | F20: =+F18+F19 -> 0 | G20: =+G18+G19 -> 0 | H20: =+H18+H19 -> 0 | I20: =SUM(I19) -> 799081 | J20: =+J18+J19 -> 0 | K20: =+K18+K19 -> 0 | L20: =+L18+L19 -> 0 | M20: =+M18+M19 -> 0 | N20: =+N18+N19 -> 0 | O20: =+O18+O19 -> 0 | P20: =SUM(P19) -> 0 | Q20: =SUM(Q19) -> 0
A21: 労働保険料 | B21: 業務課 | C21: =明細!Q25 -> 28143 | I21: =SUM(C21:H21) -> 28143 | P21: =SUM(J21:O21) -> 0 | Q21: =+I21+P21 -> 28143
B22: マンション課 | I22: =SUM(C22:H22) -> 0 | P22: =SUM(J22:O22) -> 0 | Q22: =+I22+P22 -> 0
B23: 工事課 | I23: =SUM(C23:H23) -> 0 | P23: =SUM(J23:O23) -> 0 | Q23: =+I23+P23 -> 0
B24: 旭川営業所 | I24: =SUM(C24:H24) -> 0 | P24: =SUM(J24:O24) -> 0 | Q24: =+I24+P24 -> 0
B25: 斎場管理課 | I25: =SUM(C25:H25) -> 0 | P25: =SUM(J25:O25) -> 0 | Q25: =+I25+P25 -> 0
B26: 保険課 | I26: =SUM(C26:H26) -> 0 | P26: =SUM(J26:O26) -> 0 | Q26: =+I26+P26 -> 0
B27: 小計 | C27: =SUM(C21:C26) -> 28143 | D27: =SUM(D21:D26) -> 0 | E27: =SUM(E21:E26) -> 0 | F27: =SUM(F21:F26) -> 0 | G27: =SUM(G21:G26) -> 0 | H27: =SUM(H21:H26) -> 0 | I27: =SUM(C27:H27) -> 28143 | J27: =SUM(J21:J26) -> 0 | K27: =SUM(K21:K26) -> 0 | L27: =SUM(L21:L26) -> 0 | M27: =SUM(M21:M26) -> 0 | N27: =SUM(N21:N26) -> 0 | O27: =SUM(O21:O26) -> 0 | P27: =SUM(P21:P26) -> 0 | Q27: =SUM(K27:P27) -> 0
B28: 営業費 | I28: =SUM(C28:H28) -> 0 | P28: =SUM(P22:P27) -> 0 | Q28: =SUM(K28:P28) -> 0
B29: 合計 | C29: =+C27+C28 -> 28143 | D29: =+D27+D28 -> 0 | E29: =+E27+E28 -> 0 | F29: =+F27+F28 -> 0 | G29: =+G27+G28 -> 0 | H29: =+H27+H28 -> 0 | I29: =SUM(I28) -> 0 | J29: =+J27+J28 -> 0 | K29: =+K27+K28 -> 0 | L29: =+L27+L28 -> 0 | M29: =+M27+M28 -> 0 | N29: =+N27+N28 -> 0 | O29: =+O27+O28 -> 0 | P29: =SUM(P28) -> 0 | Q29: =SUM(Q28) -> 0
A30: 社会保険料 | B30: 業務課 | C30: =明細!R25 -> 430315 | I30: =SUM(C30:H30) -> 430315 | P30: =SUM(J30:O30) -> 0 | Q30: =+I30+P30 -> 430315
B31: マンション課 | I31: =SUM(C31:H31) -> 0 | P31: =SUM(J31:O31) -> 0 | Q31: =+I31+P31 -> 0
B32: 工事課 | I32: =SUM(C32:H32) -> 0 | P32: =SUM(J32:O32) -> 0 | Q32: =+I32+P32 -> 0
B33: 旭川営業所 | I33: =SUM(C33:H33) -> 0 | P33: =SUM(J33:O33) -> 0 | Q33: =+I33+P33 -> 0
B34: 斎場管理課 | I34: =SUM(C34:H34) -> 0 | P34: =SUM(J34:O34) -> 0 | Q34: =+I34+P34 -> 0
B35: 保険課 | I35: =SUM(C35:H35) -> 0 | P35: =SUM(J35:O35) -> 0 | Q35: =+I35+P35 -> 0
B36: 小計 | C36: =SUM(C30:C35) -> 430315 | D36: =SUM(D30:D35) -> 0 | E36: =SUM(E30:E35) -> 0 | F36: =SUM(F30:F35) -> 0 | G36: =SUM(G30:G35) -> 0 | H36: =SUM(H30:H35) -> 0 | I36: =SUM(C36:H36) -> 430315 | J36: =SUM(J30:J35) -> 0 | K36: =SUM(K30:K35) -> 0 | L36: =SUM(L30:L35) -> 0 | M36: =SUM(M30:M35) -> 0 | N36: =SUM(N30:N35) -> 0 | O36: =SUM(O30:O35) -> 0 | P36: =SUM(P30:P35) -> 0 | Q36: =SUM(K36:P36) -> 0
B37: 営業費 | I37: =SUM(C37:H37) -> 0 | P37: =SUM(P31:P36) -> 0 | Q37: =SUM(K37:P37) -> 0
B38: 合計 | C38: =+C36+C37 -> 430315 | D38: =+D36+D37 -> 0 | E38: =+E36+E37 -> 0 | F38: =+F36+F37 -> 0 | G38: =+G36+G37 -> 0 | H38: =+H36+H37 -> 0 | I38: =SUM(I37) -> 0 | J38: =+J36+J37 -> 0 | K38: =+K36+K37 -> 0 | L38: =+L36+L37 -> 0 | M38: =+M36+M37 -> 0 | N38: =+N36+N37 -> 0 | O38: =+O36+O37 -> 0 | P38: =SUM(P37) -> 0 | Q38: =SUM(Q37) -> 0
A39: 法定福利費合計 | B39: 業務課 | C39: =+C21+C30 -> 458458 | D39: =+D21+D30 -> 0 | E39: =+E21+E30 -> 0 | F39: =+F21+F30 -> 0 | G39: =+G21+G30 -> 0 | H39: =+H21+H30 -> 0 | I39: =SUM(C39:H39) -> 458458 | J39: =+J21+J30 -> 0 | K39: =+K21+K30 -> 0 | L39: =+L21+L30 -> 0 | M39: =+M21+M30 -> 0 | N39: =+N21+N30 -> 0 | O39: =+O21+O30 -> 0 | P39: =SUM(J39:O39) -> 0 | Q39: =+I39+P39 -> 458458
B40: マンション課 | C40: =+C22+C31 -> 0 | D40: =+D22+D31 -> 0 | E40: =+E22+E31 -> 0 | F40: =+F22+F31 -> 0 | G40: =+G22+G31 -> 0 | H40: =+H22+H31 -> 0 | I40: =SUM(C40:H40) -> 0 | J40: =+J22+J31 -> 0 | K40: =+K22+K31 -> 0 | L40: =+L22+L31 -> 0 | M40: =+M22+M31 -> 0 | N40: =+N22+N31 -> 0 | O40: =+O22+O31 -> 0 | P40: =SUM(J40:O40) -> 0 | Q40: =+I40+P40 -> 0
...

Sheet 明細
O1: 4月 | U1: 5月 | AA1: 6月 | AG1: 7月 | AM1: 8月 | AS1: 9月 | AY1: 10月 | BE1: 11月 | BK1: 12月 | BQ1: 1月 | BW1: 2月 | CC1: 3月
B2: 従業員区分 (0:職員 ,1:準職員 ,2:出向社員) | D2: 社員コード | E2: 氏 | F2: 名 | G2: 役職CD | H2: 役職 | I2: 仕訳部門CD | J2: 部門 | K2: 仕訳区分CD | L2: 区分 | M2: 科目CD | N2: 科目 | O2: 職員給与 | P2: 職員賞与 | Q2: 労働保険料 | R2: 社会保険料 | S2: 退職金 | T2: 通勤費 | U2: 職員給与 | V2: 職員賞与 | W2: 労働保険料 | X2: 社会保険料 | Y2: 退職金 | Z2: 通勤費 | AA2: 職員給与 | AB2: 職員賞与 | AC2: 労働保険料 | AD2: 社会保険料 | AE2: 退職金 | AF2: 通勤費 | AG2: 職員給与 | AH2: 職員賞与 | AI2: 労働保険料 | AJ2: 社会保険料 | AK2: 退職金 | AL2: 通勤費 | AM2: 職員給与 | AN2: 職員賞与 | AO2: 労働保険料 | AP2: 社会保険料 | AQ2: 退職金 | AR2: 通勤費 | AS2: 職員給与 | AT2: 職員賞与 | AU2: 労働保険料 | AV2: 社会保険料 | AW2: 退職金 | AX2: 通勤費 | AY2: 職員給与 | AZ2: 職員賞与 | BA2: 労働保険料 | BB2: 社会保険料 | BC2: 退職金 | BD2: 通勤費 | BE2: 職員給与 | BF2: 職員賞与 | BG2: 労働保険料 | BH2: 社会保険料 | BI2: 退職金 | BJ2: 通勤費 | BK2: 職員給与 | BL2: 職員賞与 | BM2: 労働保険料 | BN2: 社会保険料 | BO2: 退職金 | BP2: 通勤費 | BQ2: 職員給与 | BR2: 職員賞与 | BS2: 労働保険料 | BT2: 社会保険料 | BU2: 退職金 | BV2: 通勤費 | BW2: 職員給与 | BX2: 職員賞与 | BY2: 労働保険料 | BZ2: 社会保険料 | CA2: 退職金 | CB2: 通勤費 | CC2: 職員給与 | CD2: 職員賞与 | CE2: 労働保険料 | CF2: 社会保険料 | CG2: 退職金 | CH2: 通勤費
B3: 0 | C3: 職員 | D3: 1125 | E3: 藤井 | F3: 光幸 | G3: 4 | H3: 取締役 | I3: 6 | J3: ビル管理部 | K3: 0 | M3: 42100 | N3: 営業費 | O3: 322500 | P3: 116667 | Q3: 3929 | R3: 59480 | S3: 67083 | T3: -5619 | U3: 322500 | V3: 116667 | W3: 3983 | X3: 59480 | Y3: 67083 | Z3: 0 | AA3: 322500 | AB3: 116667 | AC3: 3983 | AD3: 59480 | AE3: 67083 | AF3: 0 | AG3: 322500 | AH3: 116667 | AI3: 3983 | AJ3: 59480 | AK3: 67083 | AL3: 0 | AM3: 322500 | AN3: 116667 | AO3: 3983 | AP3: 64794 | AQ3: 67083 | AR3: 0 | AS3: 322500 | AT3: 116667 | AU3: 3983 | AV3: 64794 | AW3: 67083 | AX3: 0 | AY3: 322500 | AZ3: 116667 | BA3: 3983 | BB3: 65342 | BC3: 67083 | BD3: 0 | BE3: 322500 | BF3: 116667 | BG3: 3983 | BH3: 65342 | BI3: 67083 | BJ3: 0 | BK3: 322500 | BL3: 116667 | BM3: 3983 | BN3: 65342 | BO3: 67083 | BP3: 0 | BQ3: 275000 | BR3: 116667 | BS3: 4202 | BT3: 59466 | BU3: 67083 | BV3: 19670 | BW3: 275000 | BX3: 116667 | BY3: 3996 | BZ3: 59466 | CA3: 67083 | CB3: 0 | CC3: 275000 | CD3: 116667 | CE3: 3996 | CF3: 59466 | CG3: 67083 | CH3: 0
B4: 0 | C4: 職員 | D4: 1174 | E4: 高橋 | F4: 和裕 | G4: 12 | H4: 副部長 | I4: 6 | J4: ビル管理部 | K4: 0 | M4: 42100 | N4: 営業費 | O4: 422000 | P4: 122166 | Q4: 6155 | R4: 84239 | S4: 11697 | T4: 108070 | U4: 422000 | V4: 122166 | W4: 5127 | X4: 84239 | Y4: 11697 | Z4: 0 | AA4: 426300 | AB4: 122166 | AC4: 5250 | AD4: 84239 | AE4: 11697 | AF4: 0 | AG4: 426300 | AH4: 122166 | AI4: 6195 | AJ4: 84239 | AK4: 11697 | AL4: 108070 | AM4: 426300 | AN4: 122166 | AO4: 5169 | AP4: 84239 | AQ4: 11697 | AR4: 0 | AS4: 426300 | AT4: 122166 | AU4: 5169 | AV4: 84239 | AW4: 11697 | AX4: 0 | AY4: 426300 | AZ4: 122166 | BA4: 6195 | BB4: 89505 | BC4: 11697 | BD4: 108070 | BE4: 426300 | BF4: 122166 | BG4: 5169 | BH4: 89505 | BI4: 11697 | BJ4: 0 | BK4: 426300 | BL4: 122166 | BM4: 5169 | BN4: 89505 | BO4: 11697 | BP4: 0 | BQ4: 422000 | BR4: 122166 | BS4: 6680 | BT4: 84217 | BU4: 11697 | BV4: 108070 | BW4: 422000 | BX4: 122166 | BY4: 5545 | BZ4: 84217 | CA4: 11697 | CB4: 0 | CC4: 422000 | CD4: 122166 | CE4: 5545 | CF4: 84217 | CG4: 11697 | CH4: 0
B5: 0 | C5: 職員 | D5: 1156 | E5: 寺西 | F5: 淳浩 | G5: 14 | H5: 課長 | I5: 6 | J5: ビル管理部 | K5: 0 | M5: 42100 | N5: 営業費 | O5: 384800 | P5: 106000 | Q5: 5292 | R5: 77266 | S5: 17839 | T5: 70140 | U5: 384800 | V5: 106000 | W5: 4627 | X5: 77266 | Y5: 17839 | Z5: 0 | AA5: 387500 | AB5: 106000 | AC5: 4703 | AD5: 77266 | AE5: 17839 | AF5: 0 | AG5: 387500 | AH5: 106000 | AI5: 5318 | AJ5: 77266 | AK5: 17839 | AL5: 70140 | AM5: 387500 | AN5: 106000 | AO5: 4651 | AP5: 77266 | AQ5: 17839 | AR5: 0 | AS5: 387500 | AT5: 106000 | AU5: 4651 | AV5: 77266 | AW5: 17839 | AX5: 0 | AY5: 387500 | AZ5: 106000 | BA5: 5318 | BB5: 77992 | BC5: 17839 | BD5: 70140 | BE5: 387500 | BF5: 106000 | BG5: 4651 | BH5: 77992 | BI5: 17839 | BJ5: 0 | BK5: 387500 | BL5: 106000 | BM5: 4651 | BN5: 77992 | BO5: 17839 | BP5: 0 | BQ5: 384800 | BR5: 106000 | BS5: 5743 | BT5: 77245 | BU5: 17839 | BV5: 70140 | BW5: 384800 | BX5: 106000 | BY5: 5008 | BZ5: 77245 | CA5: 17839 | CB5: 0 | CC5: 384800 | CD5: 106000 | CE5: 5008 | CF5: 77245 | CG5: 17839 | CH5: 0
B6: 0 | C6: 職員 | D6: 1313 | E6: 岡部 | F6: 慎悟 | G6: 14 | H6: 課長 | I6: 6 | J6: ビル管理部 | K6: 0 | M6: 42100 | N6: 営業費 | O6: 198250 | P6: 56250 | Q6: 2824 | R6: 39120 | S6: 9377 | T6: 44745 | U6: 198250 | V6: 56250 | W6: 2399 | X6: 39120 | Y6: 9377 | Z6: 0 | AA6: 198250 | AB6: 56250 | AC6: 2399 | AD6: 39120 | AE6: 9377 | AF6: 0 | AG6: 198250 | AH6: 56250 | AI6: 2824 | AJ6: 39120 | AK6: 9377 | AL6: 44745 | AM6: 198250 | AN6: 56250 | AO6: 2399 | AP6: 39120 | AQ6: 9377 | AR6: 0 | AS6: 198250 | AT6: 56250 | AU6: 2399 | AV6: 39120 | AW6: 9377 | AX6: 0 | AY6: 198250 | AZ6: 56250 | BA6: 2824 | BB6: 39483 | BC6: 9377 | BD6: 44745 | BE6: 198250 | BF6: 56250 | BG6: 2399 | BH6: 39483 | BI6: 9377 | BJ6: 0 | BK6: 198250 | BL6: 56250 | BM6: 2399 | BN6: 39483 | BO6: 9377 | BP6: 0 | BQ6: 198250 | BR6: 56250 | BS6: 3065 | BT6: 39109 | BU6: 9377 | BV6: 44745 | BW6: 198250 | BX6: 56250 | BY6: 2596 | BZ6: 39109 | CA6: 9377 | CB6: 0 | CC6: 198250 | CD6: 56250 | CE6: 2596 | CF6: 39109 | CG6: 9377 | CH6: 0
B7: 0 | C7: 職員 | D7: 1133 | E7: 笹木 | F7: 美幸 | G7: 15 | H7: 担当課長 | I7: 6 | J7: ビル管理部 | K7: 0 | M7: 42100 | N7: 営業費 | O7: 326400 | P7: 100166 | Q7: 4786 | R7: 65949 | S7: 9321 | T7: 81140 | U7: 326400 | V7: 100166 | W7: 4015 | X7: 65949 | Y7: 9321 | Z7: 0 | AA7: 330000 | AB7: 100166 | AC7: 4118 | AD7: 65949 | AE7: 9321 | AF7: 0 | AG7: 330000 | AH7: 100166 | AI7: 4820 | AJ7: 65949 | AK7: 9321 | AL7: 81140 | AM7: 330000 | AN7: 100166 | AO7: 4049 | AP7: 65949 | AQ7: 9321 | AR7: 0 | AS7: 330000 | AT7: 100166 | AU7: 4049 | AV7: 65949 | AW7: 9321 | AX7: 0 | AY7: 330000 | AZ7: 100166 | BA7: 4820 | BB7: 69542 | BC7: 9321 | BD7: 81140 | BE7: 330000 | BF7: 100166 | BG7: 4049 | BH7: 69542 | BI7: 9321 | BJ7: 0 | BK7: 330000 | BL7: 100166 | BM7: 4049 | BN7: 69542 | BO7: 9321 | BP7: 0 | BQ7: 326400 | BR7: 100166 | BS7: 5190 | BT7: 65932 | BU7: 9321 | BV7: 81140 | BW7: 326400 | BX7: 100166 | BY7: 4338 | BZ7: 65932 | CA7: 9321 | CB7: 0 | CC7: 326400 | CD7: 100166 | CE7: 4338 | CF7: 65932 | CG7: 9321 | CH7: 0
B8: 0 | C8: 職員 | D8: 1151 | E8: 鈴木 | F8: 広美 | G8: 18 | H8: 課長代理 | I8: 6 | J8: ビル管理部 | K8: 0 | M8: 42100 | N8: 営業費 | O8: 312200 | P8: 92000 | Q8: 3808 | R8: 58735 | S8: 14961 | T8: 0 | U8: 312200 | V8: 92000 | W8: 3808 | X8: 58735 | Y8: 14961 | Z8: 0 | AA8: 314600 | AB8: 92000 | AC8: 3877 | AD8: 58735 | AE8: 14961 | AF8: 0 | AG8: 314600 | AH8: 92000 | AI8: 3831 | AJ8: 58735 | AK8: 14961 | AL8: 0 | AM8: 314600 | AN8: 92000 | AO8: 3831 | AP8: 58735 | AQ8: 14961 | AR8: 0 | AS8: 314600 | AT8: 92000 | AU8: 3831 | AV8: 58735 | AW8: 14961 | AX8: 0 | AY8: 314600 | AZ8: 92000 | BA8: 3831 | BB8: 62257 | BC8: 14961 | BD8: 0 | BE8: 314600 | BF8: 92000 | BG8: 3831 | BH8: 62257 | BI8: 14961 | BJ8: 0 | BK8: 314600 | BL8: 92000 | BM8: 3831 | BN8: 62257 | BO8: 14961 | BP8: 0 | BQ8: 312200 | BR8: 92000 | BS8: 4117 | BT8: 52810 | BU8: 14961 | BV8: 0 | BW8: 312200 | BX8: 92000 | BY8: 4117 | BZ8: 58720 | CA8: 14961 | CB8: 0 | CC8: 312200 | CD8: 92000 | CE8: 4117 | CF8: 58720 | CG8: 14961 | CH8: 0
B9: 0 | C9: 職員 | D9: 1242 | E9: 高橋 | F9: 美奈子 | G9: 22 | H9: 職員 | I9: 6 | J9: ビル管理部 | K9: 0 | M9: 42100 | N9: 営業費 | O9: 233895 | P9: 61833 | Q9: 3621 | R9: 48192 | S9: 11927 | T9: 89490 | U9: 233911 | V9: 61833 | W9: 2787 | X9: 48192 | Y9: 11927 | Z9: 0 | AA9: 234616 | AB9: 61833 | AC9: 2853 | AD9: 48192 | AE9: 11927 | AF9: 0 | AG9: 234600 | AH9: 61833 | AI9: 3644 | AJ9: 48192 | AK9: 11927 | AL9: 89490 | AM9: 234600 | AN9: 61833 | AO9: 2794 | AP9: 48192 | AQ9: 11927 | AR9: 0 | AS9: 234600 | AT9: 61833 | AU9: 2794 | AV9: 48192 | AW9: 11927 | AX9: 0 | AY9: 234600 | AZ9: 61833 | BA9: 3644 | BB9: 48653 | BC9: 11927 | BD9: 89490 | BE9: 234600 | BF9: 61833 | BG9: 2794 | BH9: 48653 | BI9: 11927 | BJ9: 0 | BK9: 234600 | BL9: 61833 | BM9: 2794 | BN9: 48653 | BO9: 11927 | BP9: 0 | BQ9: 232300 | BR9: 61833 | BS9: 3941 | BT9: 48179 | BU9: 11927 | BV9: 89490 | BW9: 232300 | BX9: 61833 | BY9: 3002 | BZ9: 48179 | CA9: 11927 | CB9: 0 | CC9: 232300 | CD9: 61833 | CE9: 3002 | CF9: 48179 | CG9: 11927 | CH9: 0
B10: 0 | C10: 職員 | D10: 1278 | E10: 佐々木 | F10: 朋子 | G10: 22 | H10: 職員 | I10: 6 | J10: ビル管理部 | K10: 0 | M10: 42100 | N10: 営業費 | O10: 254786 | P10: 68500 | Q10: 3225 | R10: 49189 | S10: 12862 | T10: 29550 | U10: 243800 | V10: 68500 | W10: 3048 | X10: 49189 | Y10: 12862 | Z10: 0 | AA10: 246206 | AB10: 68500 | AC10: 3011 | AD10: 49189 | AE10: 12862 | AF10: 0 | AG10: 246100 | AH10: 68500 | AI10: 3246 | AJ10: 49189 | AK10: 12862 | AL10: 29550 | AM10: 246100 | AN10: 68500 | AO10: 2966 | AP10: 49189 | AQ10: 12862 | AR10: 0 | AS10: 246100 | AT10: 68500 | AU10: 2966 | AV10: 49189 | AW10: 12862 | AX10: 0 | AY10: 246100 | AZ10: 68500 | BA10: 3246 | BB10: 49650 | BC10: 12862 | BD10: 29550 | BE10: 246100 | BF10: 68500 | BG10: 2966 | BH10: 49650 | BI10: 12862 | BJ10: 0 | BK10: 246100 | BL10: 68500 | BM10: 2966 | BN10: 49650 | BO10: 12862 | BP10: 0 | BQ10: 243800 | BR10: 68500 | BS10: 3496 | BT10: 49176 | BU10: 12862 | BV10: 29550 | BW10: 248455 | BX10: 68500 | BY10: 3185 | BZ10: 49176 | CA10: 12862 | CB10: 0 | CC10: 243800 | CD10: 68500 | CE10: 3234 | CF10: 49176 | CG10: 12862 | CH10: 0
B11: 0 | C11: 職員 | D11: 1339 | E11: 佐藤 | F11: 元彦 | G11: 22 | H11: 職員 | I11: 6 | J11: ビル管理部 | K11: 0 | M11: 42100 | N11: 営業費 | O11: 149650 | P11: 33833 | Q11: 1936 | R11: 27549 | S11: 8251 | T11: 17240 | U11: 160050 | V11: 33833 | W11: 1732 | X11: 27549 | Y11: 8251 | Z11: 0 | AA11: 159600 | AB11: 33833 | AC11: 1863 | AD11: 27549 | AE11: 8251 | AF11: 0 | AG11: 157050 | AH11: 33833 | AI11: 1991 | AJ11: 27549 | AK11: 8251 | AL11: 17240 | AM11: 151100 | AN11: 33833 | AO11: 1803 | AP11: 27549 | AQ11: 8251 | AR11: 0 | AS11: 154950 | AT11: 33833 | AU11: 1746 | AV11: 27549 | AW11: 8251 | AX11: 0 | AY11: 163300 | AZ11: 33833 | BA11: 1946 | BB11: 29309 | BC11: 8251 | BD11: 17240 | BE11: 157050 | BF11: 33833 | BG11: 1862 | BH11: 29309 | BI11: 8251 | BJ11: 0 | BK11: 156900 | BL11: 33833 | BM11: 1803 | BN11: 29309 | BO11: 8251 | BP11: 0 | BQ11: 145800 | BR11: 33833 | BS11: 2125 | BT11: 27541 | BU11: 8251 | BV11: 17240 | BW11: 154450 | BX11: 33833 | BY11: 1840 | BZ11: 27541 | CA11: 8251 | CB11: 0 | CC11: 153800 | CD11: 33833 | CE11: 1931 | CF11: 27541 | CG11: 8251 | CH11: 0
B12: 0 | C12: 職員 | D12: 1464 | E12: 魚谷 | F12: 光昭 | G12: 23 | H12: 嘱託 | I12: 6 | J12: ビル管理部 | K12: 0 | M12: 42100 | N12: 営業費 | O12: 250000 | P12: 41666 | Q12: 3231 | R12: 45176 | S12: 0 | T12: 48520 | U12: 250000 | V12: 41666 | W12: 2770 | X12: 45176 | Y12: 0 | Z12: 0 | AA12: 250000 | AB12: 41666 | AC12: 2770 | AD12: 45176 | AE12: 0 | AF12: 0 | AG12: 250000 | AH12: 41666 | AI12: 3231 | AJ12: 45176 | AK12: 0 | AL12: 48520 | AM12: 250000 | AN12: 41666 | AO12: 2770 | AP12: 45176 | AQ12: 0 | AR12: 0 | AS12: 250000 | AT12: 41666 | AU12: 2770 | AV12: 45176 | AW12: 0 | AX12: 0 | AY12: 253662 | AZ12: 41666 | BA12: 3231 | BB12: 45637 | BC12: 0 | BD12: 48520 | BE12: 254049 | BF12: 41666 | BG12: 2804 | BH12: 45637 | BI12: 0 | BJ12: 0 | BK12: 250000 | BL12: 41666 | BM12: 2808 | BN12: 45637 | BO12: 0 | BP12: 0 | BQ12: 250000 | BR12: 41666 | BS12: 3529 | BT12: 45163 | BU12: 0 | BV12: 48520 | BW12: 250000 | BX12: 41666 | BY12: 3020 | BZ12: 45163 | CA12: 0 | CB12: 0 | CC12: 250000 | CD12: 41666 | CE12: 3020 | CF12: 45163 | CG12: 0 | CH12: 0
O13: =SUM(O3:O12) -> 2854481 | P13: =SUM(P3:P12) -> 799081 | Q13: =SUM(Q3:Q12) -> 38807 | R13: =SUM(R3:R12) -> 554895 | S13: =SUM(S3:S12) -> 163318 | T13: =SUM(T3:T12) -> 483276 | U13: =SUM(U3:U12) -> 2853911 | V13: =SUM(V3:V12) -> 799081 | ... CH13: =SUM(CH3:CH12) -> 0
B14: 0 | C14: 職員 | D14: 1175 | E14: 工藤 | F14: 敏晴 | G14: 12 | H14: 副部長 | I14: 6 | J14: ビル管理部 | K14: 3 | L14: 業務課 | M14: 41400 | N14: 商品原価 | O14: 416860 | P14: 124166 | Q14: 5201 | R14: 79984 | S14: 11539 | T14: 24620 | U14: 405821 | V14: 124166 | W14: 5098 | X14: 79984 | Y14: 11539 | Z14: 0 | AA14: 414807 | AB14: 124166 | AC14: 5134 | AD14: 79984 | AE14: 11539 | AF14: 0 | AG14: 411610 | AH14: 124166 | AI14: 5310 | AJ14: 79984 | AK14: 11539 | AL14: 24620 | AM14: 408941 | AN14: 124166 | AO14: 5048 | AP14: 79984 | AQ14: 11539 | AR14: 0 | AS14: 413093 | AT14: 124166 | AU14: 5023 | AV14: 79984 | AW14: 11539 | AX14: 0 | AY14: 417542 | AZ14: 124166 | BA14: 5296 | BB14: 80710 | BC14: 11539 | BD14: 24620 | BE14: 421694 | BF14: 124166 | BG14: 5104 | BH14: 80710 | BI14: 11539 | BJ14: 0 | BK14: 410048 | BL14: 124166 | BM14: 5144 | BN14: 80710 | BO14: 11539 | BP14: 0 | BQ14: 406319 | BR14: 124166 | BS14: 5646 | BT14: 79963 | BU14: 11539 | BV14: 24620 | BW14: 402220 | BX14: 124166 | BY14: 5400 | BZ14: 79963 | CA14: 11539 | CB14: 0 | CC14: 403099 | CD14: 124166 | CE14: 5357 | CF14: 79963 | CG14: 11539 | CH14: 0
B15: 0 | C15: 職員 | D15: 1482 | E15: 尾崎 | F15: 康拓 | G15: 18 | H15: 課長代理 | I15: 6 | J15: ビル管理部 | K15: 3 | L15: 業務課 | M15: 41400 | N15: 商品原価 | O15: 0 | P15: 41166 | Q15: 390 | R15: 5831 | S15: 0 | T15: 0 | U15: 313700 | V15: 41166 | W15: 3799 | X15: 6471 | Y15: 22264 | Z15: 48520 | AA15: 284611 | AB15: 41166 | AC15: 3053 | AD15: 51236 | AE15: 22264 | AF15: 0 | AG15: 298700 | AH15: 41166 | AI15: 3666 | AJ15: 51236 | AK15: 22264 | AL15: 48520 | AM15: 298700 | AN15: 41166 | AO15: 3196 | AP15: 51236 | AQ15: 22264 | AR15: 0 | AS15: 299611 | AT15: 41166 | AU15: 3196 | AV15: 51236 | AW15: 22264 | AX15: 0 | AY15: 300066 | AZ15: 41166 | BA15: 3666 | BB15: 51802 | BC15: 22264 | BD15: 48520 | BE15: 302116 | BF15: 41166 | BG15: 3209 | BH15: 51802 | BI15: 22264 | BJ15: 0 | BK15: 298700 | BL15: 41166 | BM15: 3228 | BN15: 51802 | BO15: 22264 | BP15: 0 | BQ15: 0 | BR15: 41166 | BS15: 390 | BT15: 5831 | BU15: 0 | BV15: 0 | BW15: 0 | BX15: 41166 | BY15: 390 | BZ15: 5831 | CA15: 0 | CB15: 0 | CC15: 0 | CD15: 41166 | CE15: 390 | CF15: 5831 | CG15: 0 | CH15: 0
B16: 0 | C16: 職員 | D16: 1421 | E16: 阿部 | F16: 卓 | G16: 22 | H16: 職員 | I16: 6 | J16: ビル管理部 | K16: 3 | L16: 業務課 | M16: 41400 | N16: 商品原価 | O16: 277600 | P16: 62333 | Q16: 3660 | R16: 51342 | S16: 8755 | T16: 29550 | U16: 312170 | V16: 62333 | W16: 3209 | X16: 51342 | Y16: 8755 | Z16: 0 | AA16: 297500 | AB16: 62333 | AC16: 3594 | AD16: 51342 | AE16: 8755 | AF16: 0 | AG16: 299900 | AH16: 62333 | AI16: 3679 | AJ16: 51342 | AK16: 8755 | AL16: 29550 | AM16: 289800 | AN16: 62333 | AO16: 3420 | AP16: 51342 | AQ16: 8755 | AR16: 0 | AS16: 297500 | AT16: 62333 | AU16: 3325 | AV16: 51342 | AW16: 8755 | AX16: 0 | AY16: 300700 | AZ16: 62333 | BA16: 3679 | BB16: 57820 | BC16: 8755 | BD16: 29550 | BE16: 291000 | BF16: 62333 | BG16: 3428 | BH16: 57820 | BI16: 8755 | BJ16: 0 | BK16: 291600 | BL16: 62333 | BM16: 3337 | BN16: 57820 | BO16: 8755 | BP16: 0 | BQ16: 271800 | BR16: 62333 | BS16: 3920 | BT16: 51328 | BU16: 8755 | BV16: 29550 | BW16: 278900 | BX16: 62333 | BY16: 3424 | BZ16: 51328 | CA16: 8755 | CB16: 0 | CC16: 295500 | CD16: 62333 | CE16: 3498 | CF16: 51328 | CG16: 8755 | CH16: 0
B17: 0 | C17: 職員 | D17: 1425 | E17: 清水 | F17: 吹雪 | G17: 22 | H17: 職員 | I17: 6 | J17: ビル管理部 | K17: 3 | L17: 業務課 | M17: 41400 | N17: 商品原価 | O17: 242900 | P17: 55333 | Q17: 3093 | R17: 47220 | S17: 9128 | T17: 29550 | U17: 257414 | V17: 55333 | W17: 2813 | X17: 47220 | Y17: 9128 | Z17: 0 | AA17: 257700 | AB17: 55333 | AC17: 3008 | AD17: 47220 | AE17: 9128 | AF17: 0 | AG17: 244900 | AH17: 55333 | AI17: 3235 | AJ17: 47220 | AK17: 9128 | AL17: 29550 | AM17: 283400 | AN17: 55333 | AO17: 2832 | AP17: 47220 | AQ17: 9128 | AR17: 0 | AS17: 245905 | AT17: 55333 | AU17: 3198 | AV17: 47220 | AW17: 9128 | AX17: 0 | AY17: 297618 | AZ17: 55333 | BA17: 3122 | BB17: 47681 | BC17: 9128 | BD17: 29550 | BE17: 277600 | BF17: 55333 | BG17: 3333 | BH17: 47681 | BI17: 9128 | BJ17: 0 | BK17: 275700 | BL17: 55333 | BM17: 3143 | BN17: 47681 | BO17: 9128 | BP17: 0 | BQ17: 245900 | BR17: 55333 | BS17: 3688 | BT17: 47207 | BU17: 9128 | BV17: 29550 | BW17: 242900 | BX17: 55333 | BY17: 3085 | BZ17: 47207 | CA17: 9128 | CB17: 0 | CC17: 242900 | CD17: 55333 | CE17: 3054 | CF17: 47207 | CG17: 9128 | CH17: 0
B18: 0 | C18: 職員 | D18: 1465 | E18: 早川 | F18: 徹 | G18: 22 | H18: 職員 | I18: 6 | J18: ビル管理部 | K18: 3 | L18: 業務課 | M18: 41400 | N18: 商品原価 | O18: 251800 | P18: 56500 | Q18: 3073 | R18: 42583 | S18: 12451 | T18: 24620 | U18: 247800 | V18: 56500 | W18: 2906 | X18: 42583 | Y18: 12451 | Z18: 0 | AA18: 262300 | AB18: 56500 | AC18: 2940 | AD18: 42583 | AE18: 12451 | AF18: 0 | AG18: 272200 | AH18: 56500 | AI18: 3239 | AJ18: 42583 | AK18: 12451 | AL18: 24620 | AM18: 237500 | AN18: 56500 | AO18: 3099 | AP18: 42583 | AQ18: 12451 | AR18: 0 | AS18: 237800 | AT18: 56500 | AU18: 2770 | AV18: 44479 | AW18: 12451 | AX18: 0 | AY18: 278600 | AZ18: 56500 | BA18: 3154 | BB18: 50886 | BC18: 12451 | BD18: 24620 | BE18: 288700 | BF18: 56500 | BG18: 3161 | BH18: 50886 | BI18: 12451 | BJ18: 0 | BK18: 290200 | BL18: 56500 | BM18: 3256 | BN18: 50886 | BO18: 12451 | BP18: 0 | BQ18: 227000 | BR18: 56500 | BS18: 3628 | BT18: 42571 | BU18: 12451 | BV18: 24620 | BW18: 236300 | BX18: 56500 | BY18: 2895 | BZ18: 42571 | CA18: 12451 | CB18: 0 | CC18: 244800 | CD18: 56500 | CE18: 2993 | CF18: 42571 | CG18: 12451 | CH18: 0
B19: 0 | C19: 職員 | D19: 1454 | E19: 坂本 | F19: 圭人 | G19: 22 | H19: 職員 | I19: 6 | J19: ビル管理部 | K19: 3 | L19: 業務課 | M19: 41400 | N19: 商品原価 | O19: 175700 | P19: 44500 | Q19: 2475 | R19: 33283 | S19: 11303 | T19: 39340 | U19: 186300 | V19: 44500 | W19: 2075 | X19: 33283 | Y19: 11303 | Z19: 0 | AA19: 180200 | AB19: 44500 | AC19: 2372 | AD19: 33283 | AE19: 11303 | AF19: 0 | AG19: 180200 | AH19: 44500 | AI19: 2491 | AJ19: 33283 | AK19: 11303 | AL19: 39340 | AM19: 185500 | AN19: 44500 | AO19: 2118 | AP19: 33283 | AQ19: 11303 | AR19: 0 | AS19: 193200 | AT19: 44500 | AU19: 2168 | AV19: 33283 | AW19: 11303 | AX19: 0 | AY19: 205300 | AZ19: 44500 | BA19: 2724 | BB19: 35035 | BC19: 11303 | BD19: 39340 | BE19: 204700 | BF19: 44500 | BG19: 2356 | BH19: 35035 | BI19: 11303 | BJ19: 0 | BK19: 221300 | BL19: 44500 | BM19: 2351 | BN19: 35035 | BO19: 11303 | BP19: 0 | BQ19: 174100 | BR19: 44500 | BS19: 2947 | BT19: 33273 | BU19: 11303 | BV19: 39340 | BW19: 170900 | BX19: 44500 | BY19: 2232 | BZ19: 33273 | CA19: 11303 | CB19: 0 | CC19: 178600 | CD19: 44500 | CE19: 2199 | CF19: 33273 | CG19: 11303 | CH19: 0
B20: 0 | C20: 職員 | D20: 1456 | E20: 渡邉 | F20: 裕也 | G20: 22 | H20: 職員 | I20: 6 | J20: ビル管理部 | K20: 3 | L20: 業務課 | M20: 41400 | N20: 商品原価 | O20: 253900 | P20: 50000 | Q20: 2877 | R20: 38338 | S20: 10480 | T20: 29550 | U20: 237300 | V20: 50000 | W20: 2867 | X20: 38338 | Y20: 10480 | Z20: 0 | AA20: 219900 | AB20: 50000 | AC20: 2758 | AD20: 38338 | AE20: 10480 | AF20: 0 | AG20: 225800 | AH20: 50000 | AI20: 2825 | AJ20: 38338 | AK20: 10480 | AL20: 29550 | AM20: 237800 | AN20: 50000 | AO20: 2601 | AP20: 38338 | AQ20: 10480 | AR20: 0 | AS20: 218800 | AT20: 50000 | AU20: 2715 | AV20: 38338 | AW20: 10480 | AX20: 0 | AY20: 259300 | AZ20: 50000 | BA20: 2943 | BB20: 41560 | BC20: 10480 | BD20: 29550 | BE20: 238200 | BF20: 50000 | BG20: 2919 | BH20: 41560 | BI20: 10480 | BJ20: 0 | BK20: 271400 | BL20: 50000 | BM20: 2718 | BN20: 41560 | BO20: 10480 | BP20: 0 | BQ20: 212600 | BR20: 50000 | BS20: 3454 | BT20: 38327 | BU20: 10480 | BV20: 29550 | BW20: 219200 | BX20: 50000 | BY20: 2686 | BZ20: 38327 | CA20: 10480 | CB20: 0 | CC20: 225400 | CD20: 50000 | CE20: 2756 | CF20: 38327 | CG20: 10480 | CH20: 0
B21: 0 | C21: 職員 | D21: 1466 | E21: 深田 | F21: 泰彦 | G21: 22 | H21: 職員 | I21: 6 | J21: ビル管理部 | K21: 3 | L21: 業務課 | M21: 41400 | N21: 商品原価 | O21: 252600 | P21: 54833 | Q21: 3090 | R21: 41860 | S21: 12540 | T21: 29550 | U21: 247800 | V21: 54833 | W21: 2900 | X21: 41860 | Y21: 12540 | Z21: 0 | AA21: 245000 | AB21: 54833 | AC21: 2912 | AD21: 41860 | AE21: 12540 | AF21: 0 | AG21: 245000 | AH21: 54833 | AI21: 3109 | AJ21: 41860 | AK21: 12540 | AL21: 29550 | AM21: 245000 | AN21: 54833 | AO21: 2829 | AP21: 41860 | AQ21: 12540 | AR21: 0 | AS21: 245000 | AT21: 54833 | AU21: 2829 | AV21: 41860 | AW21: 12540 | AX21: 0 | AY21: 245000 | AZ21: 54833 | BA21: 3109 | BB21: 45118 | BC21: 12540 | BD21: 29550 | BE21: 245000 | BF21: 54833 | BG21: 2829 | BH21: 45118 | BI21: 12540 | BJ21: 0 | BK21: 245000 | BL21: 54833 | BM21: 2829 | BN21: 45118 | BO21: 12540 | BP21: 0 | BQ21: 243000 | BR21: 54833 | BS21: 3360 | BT21: 41848 | BU21: 12540 | BV21: 29550 | BW21: 243000 | BX21: 54833 | BY21: 3051 | BZ21: 41848 | CA21: 12540 | CB21: 0 | CC21: 243000 | CD21: 54833 | CE21: 3051 | CF21: 41848 | CG21: 12540 | CH21: 0
B22: 0 | C22: 職員 | D22: 1257 | E22: 半田 | F22: 勝彦 | G22: 23 | H22: 嘱託 | I22: 6 | J22: ビル管理部 | K22: 3 | L22: 業務課 | M22: 41400 | N22: 商品原価 | O22: 233333 | P22: 0 | Q22: 2718 | R22: 38945 | S22: 0 | T22: 52890 | U22: 233333 | V22: 0 | W22: 2216 | X22: 38945 | Y22: 0 | Z22: 0 | AA22: 233333 | AB22: 0 | AC22: 2216 | AD22: 38945 | AE22: 0 | AF22: 0 | AG22: 233333 | AH22: 0 | AI22: 2718 | AJ22: 38945 | AK22: 0 | AL22: 52890 | AM22: 233333 | AN22: 0 | AO22: 2216 | AP22: 38945 | AQ22: 0 | AR22: 0 | AS22: 233333 | AT22: 0 | AU22: 2216 | AV22: 38945 | AW22: 0 | AX22: 0 | AY22: 233333 | AZ22: 0 | BA22: 2718 | BB22: 39406 | BC22: 0 | BD22: 52890 | BE22: 233333 | BF22: 0 | BG22: 2216 | BH22: 39406 | BI22: 0 | BJ22: 0 | BK22: 233337 | BL22: 0 | BM22: 2216 | BN22: 39406 | BO22: 0 | BP22: 0 | BQ22: 233333 | BR22: 0 | BS22: 3005 | BT22: 38932 | BU22: 0 | BV22: 52890 | BW22: 233333 | BX22: 0 | BY22: 2449 | BZ22: 38932 | CA22: 0 | CB22: 0 | CC22: 233333 | CD22: 0 | CE22: 2449 | CF22: 38932 | CG22: 0 | CH22: 0
B23: 0 | C23: 職員 | D23: 1246 | E23: 佐藤 | F23: 弘 | G23: 22 | H23: 職員 | I23: 6 | J23: ビル管理部 | K23: 3 | L23: 業務課 | M23: 41400 | N23: 商品原価 | O23: 318200 | P23: 0 | Q23: 1566 | R23: 50929 | S23: 0 | T23: 75770 | U23: 318200 | V23: 0 | W23: 1263 | X23: 50929 | Y23: 0 | Z23: 0 | AA23: 318200 | AB23: 0 | AC23: 1263 | AD23: 50929 | AE23: 0 | AF23: 0 | AG23: 318200 | AH23: 0 | AI23: 1465 | AJ23: 50929 | AK23: 0 | AL23: 50514 | AM23: 318200 | AN23: 0 | AO23: 1263 | AP23: 50929 | AQ23: 0 | AR23: 0 | AS23: 318200 | AT23: 0 | AU23: 0 | AV23: 50929 | AW23: 0 | AX23: 0 | AY23: 0 | AZ23: 0 | BA23: 0 | BB23: 0 | BC23: 0 | BD23: 0 | BE23: 0 | BF23: 0 | BG23: 0 | BH23: 0 | BI23: 0 | BJ23: 0 | BK23: 7700 | BL23: 0 | BM23: 0 | BN23: 0 | BO23: 0 | BP23: 0 | BQ23: 318200 | BR23: 0 | BS23: 1996 | BT23: 50912 | BU23: 0 | BV23: 75770 | BW23: 318200 | BX23: 0 | BY23: 1579 | BZ23: 50912 | CA23: 0 | CB23: 0 | CC23: 318200 | CD23: 0 | CE23: 1579 | CF23: 50912 | CG23: 0 | CH23: 0
B24: 1 | C24: 準職員 | D24: 6038 | E24: 佐藤 | F24: 弘 | G24: 24 | H24: 準職員 | I24: 6 | J24: ビル管理部 | K24: 3 | L24: 業務課 | M24: 41400 | N24: 商品原価 | O24: 0 | P24: 0 | Q24: 0 | R24: 0 | S24: 0 | T24: 0 | U24: 0 | V24: 0 | W24: 0 | X24: 0 | Y24: 0 | Z24: 0 | AA24: 0 | AB24: 0 | AC24: 0 | AD24: 0 | AE24: 0 | AF24: 0 | AG24: 0 | AH24: 0 | AI24: 0 | AJ24: 0 | AK24: 0 | AL24: 0 | AM24: 0 | AN24: 0 | AO24: 0 | AP24: 0 | AQ24: 0 | AR24: 0 | AS24: 0 | AT24: 0 | AU24: 0 | AV24: 0 | AW24: 0 | AX24: 0 | AY24: 0 | AZ24: 0 | BA24: 0 | BB24: 0 | BC24: 0 | BD24: 0 | BE24: 251580 | BF24: 0 | BG24: 2649 | BH24: 51530 | BI24: 0 | BJ24: 27350 | BK24: 229100 | BL24: 0 | BM24: 2435 | BN24: 51530 | BO24: 0 | BP24: 27350 | BQ24: 0 | BR24: 0 | BS24: 0 | BT24: 0 | BU24: 0 | BV24: 0 | BW24: 0 | BX24: 0 | BY24: 0 | BZ24: 0 | CA24: 0 | CB24: 0 | CC24: 0 | CD24: 0 | CE24: 0 | CF24: 0 | CG24: 0 | CH24: 0
O25: =SUM(O14:O24) -> 2422893 | P25: =SUM(P14:P24) -> 488831 | Q25: =SUM(Q14:Q24) -> 28143 | R25: =SUM(R14:R24) -> 430315 | S25: =SUM(S14:S24) -> 76196 | T25: =SUM(T14:T24) -> 335440 | U25: =SUM(U14:U24) -> 2759838 | V25: =SUM(V14:V24) -> 488831 | ... CH25: =SUM(CH14:CH24) -> 0
B26: 0 | C26: 職員 | D26: 1370 | E26: 阿部 | F26: 拓也 | G26: 18 | H26: 課長代理 | I26: 6 | J26: ビル管理部 | K26: 4 | L26: マンション管理課 | M26: 41400 | N26: 商品原価 | O26: 334400 | P26: 74166 | Q26: 4166 | R26: 62021 | S26: 14418 | T26: 44270 | U26: 328200 | V26: 74166 | W26: 3849 | X26: 62021 | Y26: 14418 | Z26: 0 | AA26: 315400 | AB26: 74166 | AC26: 3870 | AD26: 62021 | AE26: 14418 | AF26: 0 | AG26: 312400 | AH26: 74166 | AI26: 4089 | AJ26: 62021 | AK26: 14418 | AL26: 44270 | AM26: 315600 | AN26: 74166 | AO26: 3640 | AP26: 62021 | AQ26: 14418 | AR26: 0 | AS26: 320100 | AT26: 74166 | AU26: 3671 | AV26: 62021 | AW26: 14418 | AX26: 0 | AY26: 328900 | AZ26: 74166 | BA26: 4291 | BB26: 62622 | BC26: 14418 | BD26: 44270 | BE26: 328900 | BF26: 74166 | BG26: 3797 | BH26: 62622 | BI26: 14418 | BJ26: 0 | BK26: 336600 | BL26: 74166 | BM26: 3797 | BN26: 62622 | BO26: 14418 | BP26: 0 | BQ26: 328600 | BR26: 74166 | BS26: 4465 | BT26: 62004 | BU26: 14418 | BV26: 44270 | BW26: 328200 | BX26: 74166 | BY26: 4119 | BZ26: 62004 | CA26: 14418 | CB26: 0 | CC26: 323500 | CD26: 74166 | CE26: 4115 | CF26: 62004 | CG26: 14418 | CH26: 0
B27: 0 | C27: 職員 | D27: 1452 | E27: 山本 | F27: 孝人 | G27: 18 | H27: 課長代理 | I27: 6 | J27: ビル管理部 | K27: 4 | L27: マンション管理課 | M27: 41400 | N27: 商品原価 | O27: 293300 | P27: 84333 | Q27: 3968 | R27: 57549 | S27: 9554 | T27: 43510 | U27: 293300 | V27: 84333 | W27: 3555 | X27: 57549 | Y27: 9554 | Z27: 0 | AA27: 296000 | AB27: 84333 | AC27: 3632 | AD27: 57549 | AE27: 9554 | AF27: 0 | AG27: 296000 | AH27: 84333 | AI27: 3993 | AJ27: 57549 | AK27: 9554 | AL27: 43510 | AM27: 296000 | AN27: 84333 | AO27: 3580 | AP27: 57549 | AQ27: 9554 | AR27: 0 | AS27: 296000 | AT27: 84333 | AU27: 3580 | AV27: 57549 | AW27: 9554 | AX27: 0 | AY27: 296000 | AZ27: 84333 | BA27: 3993 | BB27: 58080 | BC27: 9554 | BD27: 43510 | BE27: 296000 | BF27: 84333 | BG27: 3580 | BH27: 58080 | BI27: 9554 | BJ27: 0 | BK27: 296000 | BL27: 84333 | BM27: 3580 | BN27: 58080 | BO27: 9554 | BP27: 0 | BQ27: 293300 | BR27: 84333 | BS27: 4301 | BT27: 57534 | BU27: 9554 | BV27: 43510 | BW27: 293300 | BX27: 84333 | BY27: 3845 | BZ27: 57534 | CA27: 9554 | CB27: 0 | CC27: 293300 | CD27: 84333 | CE27: 3845 | CF27: 57534 | CG27: 9554 | CH27: 0
B28: 0 | C28: 職員 | D28: 1302 | E28: 中島 | F28: 一志 | G28: 22 | H28: 職員 | I28: 6 | J28: ビル管理部 | K28: 4 | L28: マンション管理課 | M28: 41400 | N28: 商品原価 | O28: 307500 | P28: 71833 | Q28: 4005 | R28: 58675 | S28: 13764 | T28: 52890 | U28: 307500 | V28: 71833 | W28: 3581 | X28: 58675 | Y28: 13764 | Z28: 0 | AA28: 301500 | AB28: 71833 | AC28: 3647 | AD28: 58675 | AE28: 13764 | AF28: 0 | AG28: 301500 | AH28: 71833 | AI28: 4026 | AJ28: 58675 | AK28: 13764 | AL28: 52890 | AM28: 309800 | AN28: 71833 | AO28: 3524 | AP28: 58675 | AQ28: 13764 | AR28: 0 | AS28: 301500 | AT28: 71833 | AU28: 3603 | AV28: 58675 | AW28: 13764 | AX28: 0 | AY28: 309800 | AZ28: 71833 | BA28: 4026 | BB28: 59241 | BC28: 13764 | BD28: 52890 | BE28: 301500 | BF28: 71833 | BG28: 3603 | BH28: 59241 | BI28: 13764 | BJ28: 0 | BK28: 304700 | BL28: 71833 | BM28: 3524 | BN28: 59241 | BO28: 13764 | BP28: 0 | BQ28: 299200 | BR28: 71833 | BS28: 4387 | BT28: 58659 | BU28: 13764 | BV28: 52890 | BW28: 302400 | BX28: 71833 | BY28: 3799 | BZ28: 58659 | CA28: 13764 | CB28: 0 | CC28: 299200 | CD28: 71833 | CE28: 3833 | CF28: 58659 | CG28: 13764 | CH28: 0
B29: 0 | C29: 職員 | D29: 1426 | E29: 冨田 | F29: 晴美 | G29: 22 | H29: 職員 | I29: 6 | J29: ビル管理部 | K29: 4 | L29: マンション管理課 | M29: 41400 | N29: 商品原価 | O29: 219904 | P29: 51166 | Q29: 2720 | R29: 40605 | S29: 6055 | T29: 29550 | U29: 220896 | V29: 51166 | W29: 2554 | X29: 40605 | Y29: 6055 | Z29: 0 | AA29: 232091 | AB29: 51166 | AC29: 2611 | AD29: 40605 | AE29: 6055 | AF29: 0 | AG29: 214044 | AH29: 51166 | AI29: 2950 | AJ29: 40605 | AK29: 6055 | AL29: 29550 | AM29: 210634 | AN29: 51166 | AO29: 2499 | AP29: 40605 | AQ29: 6055 | AR29: 0 | AS29: 209300 | AT29: 51166 | AU29: 2466 | AV29: 40605 | AW29: 6055 | AX29: 0 | AY29: 209300 | AZ29: 51166 | BA29: 2735 | BB29: 40994 | BC29: 6055 | BD29: 29550 | BE29: 217010 | BF29: 51166 | BG29: 2454 | BH29: 40994 | BI29: 6055 | BJ29: 0 | BK29: 211946 | BL29: 51166 | BM29: 2528 | BN29: 40994 | BO29: 6055 | BP29: 0 | BQ29: 207700 | BR29: 51166 | BS29: 2982 | BT29: 40594 | BU29: 6055 | BV29: 29550 | BW29: 207700 | BX29: 51166 | BY29: 2644 | BZ29: 40594 | CA29: 6055 | CB29: 0 | CC29: 207700 | CD29: 51166 | CE29: 2644 | CF29: 40594 | CG29: 6055 | CH29: 0
B30: 0 | C30: 職員 | D30: 1427 | E30: 藤井 | F30: さつき | G30: 22 | H30: 職員 | I30: 6 | J30: ビル管理部 | K30: 4 | L30: マンション管理課 | M30: 41400 | N30: 商品原価 | O30: 217633 | P30: 54666 | Q30: 2877 | R30: 41128 | S30: 7338 | T30: 44270 | U30: 210467 | V30: 54666 | W30: 2566 | X30: 41128 | Y30: 7338 | Z30: 0 | AA30: 210211 | AB30: 54666 | AC30: 2556 | AD30: 41128 | AE30: 7338 | AF30: 0 | AG30: 209458 | AH30: 54666 | AI30: 2915 | AJ30: 41128 | AK30: 7338 | AL30: 44270 | AM30: 208667 | AN30: 54666 | AO30: 2488 | AP30: 41128 | AQ30: 7338 | AR30: 0 | AS30: 207400 | AT30: 54666 | AU30: 2481 | AV30: 41128 | AW30: 7338 | AX30: 0 | AY30: 212309 | AZ30: 54666 | BA30: 2889 | BB30: 41517 | BC30: 7338 | BD30: 44270 | BE30: 217219 | BF30: 54666 | BG30: 2516 | BH30: 41517 | BI30: 7338 | BJ30: 0 | BK30: 208811 | BL30: 54666 | BM30: 2562 | BN30: 41517 | BO30: 7338 | BP30: 0 | BQ30: 207438 | BR30: 54666 | BS30: 3133 | BT30: 41117 | BU30: 7338 | BV30: 44270 | BW30: 208222 | BX30: 54666 | BY30: 2675 | BZ30: 41117 | CA30: 7338 | CB30: 0 | CC30: 206027 | CD30: 54666 | CE30: 2683 | CF30: 41117 | CG30: 7338 | CH30: 0
O31: =SUM(O26:O30) -> 1372737 | P31: =SUM(P26:P30) -> 336164 | Q31: =SUM(Q26:Q30) -> 17736 | R31: =SUM(R26:R30) -> 259978 | S31: =SUM(S26:S30) -> 51129 | T31: =SUM(T26:T30) -> 214490 | U31: =SUM(U26:U30) -> 1360363 | V31: =SUM(V26:V30) -> 336164 | ... CH31: =SUM(CH26:CH30) -> 0
B32: 0 | C32: 職員 | D32: 1313 | E32: 岡部 | F32: 慎悟 | G32: 14 | H32: 課長 | I32: 6 | J32: ビル管理部 | K32: 10 | L32: 保険課 | M32: 41400 | N32: 商品原価 | O32: 198250 | P32: 56250 | Q32: 2824 | R32: 39120 | S32: 9377 | T32: 44745 | U32: 198250 | V32: 56250 | W32: 2399 | X32: 39120 | Y32: 9377 | Z32: 0 | AA32: 198250 | AB32: 56250 | AC32: 2399 | AD32: 39120 | AE32: 9377 | AF32: 0 | AG32: 198250 | AH32: 56250 | AI32: 2824 | AJ32: 39120 | AK32: 9377 | AL32: 44745 | AM32: 198250 | AN32: 56250 | AO32: 2399 | AP32: 39120 | AQ32: 9377 | AR32: 0 | AS32: 198250 | AT32: 56250 | AU32: 2399 | AV32: 39120 | AW32: 9377 | AX32: 0 | AY32: 198250 | AZ32: 56250 | BA32: 2824 | BB32: 39483 | BC32: 9377 | BD32: 44745 | BE32: 198250 | BF32: 56250 | BG32: 2399 | BH32: 39483 | BI32: 9377 | BJ32: 0 | BK32: 198250 | BL32: 56250 | BM32: 2399 | BN32: 39483 | BO32: 9377 | BP32: 0 | BQ32: 198250 | BR32: 56250 | BS32: 3065 | BT32: 39109 | BU32: 9377 | BV32: 44745 | BW32: 198250 | BX32: 56250 | BY32: 2596 | BZ32: 39109 | CA32: 9377 | CB32: 0 | CC32: 198250 | CD32: 56250 | CE32: 2596 | CF32: 39109 | CG32: 9377 | CH32: 0
O33: =SUM(O32) -> 198250 | P33: =SUM(P32) -> 56250 | Q33: =SUM(Q32) -> 2824 | R33: =SUM(R32) -> 39120 | S33: =SUM(S32) -> 9377 | T33: =SUM(T32) -> 44745 | U33: =SUM(U32) -> 198250 | V33: =SUM(V32) -> 56250 | ... CH33: =SUM(CH32) -> 0
B34: 0 | C34: 職員 | D34: 1104 | E34: 熊谷 | F34: 啓治 | G34: 14 | H34: 課長 | I34: 6 | J34: ビル管理部 | K34: 6 | L34: 工事課 | M34: 41400 | N34: 商品原価 | O34: 388600 | P34: 111500 | Q34: 4948 | R34: 73594 | S34: 19418 | T34: 24620 | U34: 388600 | V34: 111500 | W34: 4714 | X34: 73594 | Y34: 19418 | Z34: 0 | AA34: 388600 | AB34: 111500 | AC34: 4714 | AD34: 73594 | AE34: 19418 | AF34: 0 | AG34: 388600 | AH34: 111500 | AI34: 4595 | AJ34: 73594 | AK34: 19418 | AL34: -12540 | AM34: 388600 | AN34: 111500 | AO34: 4714 | AP34: 73594 | AQ34: 19418 | AR34: 0 | AS34: 388600 | AT34: 111500 | AU34: 4714 | AV34: 73594 | AW34: 19418 | AX34: 0 | AY34: 388600 | AZ34: 111500 | BA34: 4714 | BB34: 74267 | BC34: 19418 | BD34: 0 | BE34: 388600 | BF34: 111500 | BG34: 4714 | BH34: 74267 | BI34: 19418 | BJ34: 0 | BK34: 388600 | BL34: 111500 | BM34: 4714 | BN34: 74267 | BO34: 19418 | BP34: 0 | BQ34: 388600 | BR34: 111500 | BS34: 5358 | BT34: 73575 | BU34: 19418 | BV34: 24620 | BW34: 388600 | BX34: 111500 | BY34: 5099 | BZ34: 73575 | CA34: 19418 | CB34: 0 | CC34: 388600 | CD34: 111500 | CE34: 5099 | CF34: 73575 | CG34: 19418 | CH34: 0
B35: 0 | C35: 職員 | D35: 1369 | E35: 川畑 | F35: 諭史 | G35: 14 | H35: 課長 | I35: 6 | J35: ビル管理部 | K35: 6 | L35: 工事課 | M35: 41400 | N35: 商品原価 | O35: 324494 | P35: 98333 | Q35: 4479 | R35: 65634 | S35: 22360 | T35: 49180 | U35: 326503 | V35: 98333 | W35: 3984 | X35: 65634 | Y35: 22360 | Z35: 0 | AA35: 327906 | AB35: 98333 | AC35: 4114 | AD35: 65634 | AE35: 22360 | AF35: 0 | AG35: 327900 | AH35: 98333 | AI35: 4484 | AJ35: 65634 | AK35: 22360 | AL35: 49180 | AM35: 327900 | AN35: 98333 | AO35: 4016 | AP35: 65634 | AQ35: 22360 | AR35: 0 | AS35: 327900 | AT35: 98333 | AU35: 4016 | AV35: 65634 | AW35: 22360 | AX35: 0 | AY35: 351900 | AZ35: 98333 | BA35: 4712 | BB35: 66235 | BC35: 22360 | BD35: 49180 | BE35: 352422 | BF35: 98333 | BG35: 4244 | BH35: 66235 | BI35: 22360 | BJ35: 0 | BK35: 351900 | BL35: 98333 | BM35: 4249 | BN35: 66235 | BO35: 22360 | BP35: 0 | BQ35: 324247 | BR35: 98333 | BS35: 4816 | BT35: 65617 | BU35: 22360 | BV35: 49180 | BW35: 324989 | BX35: 98333 | BY35: 4302 | BZ35: 65617 | CA35: 22360 | CB35: 0 | CC35: 327462 | CD35: 98333 | CE35: 4310 | CF35: 65617 | CG35: 22360 | CH35: 0
B36: 0 | C36: 職員 | D36: 1339 | E36: 佐藤 | F36: 元彦 | G36: 22 | H36: 職員 | I36: 6 | J36: ビル管理部 | K36: 6 | L36: 工事課 | M36: 41400 | N36: 商品原価 | O36: 149650 | P36: 33833 | Q36: 1936 | R36: 27549 | S36: 8251 | T36: 17240 | U36: 160050 | V36: 33833 | W36: 1732 | X36: 27549 | Y36: 8251 | Z36: 0 | AA36: 159600 | AB36: 33833 | AC36: 1863 | AD36: 27549 | AE36: 8251 | AF36: 0 | AG36: 157050 | AH36: 33833 | AI36: 1991 | AJ36: 27549 | AK36: 8251 | AL36: 17240 | AM36: 151100 | AN36: 33833 | AO36: 1803 | AP36: 27549 | AQ36: 8251 | AR36: 0 | AS36: 154950 | AT36: 33833 | AU36: 1746 | AV36: 27549 | AW36: 8251 | AX36: 0 | AY36: 163300 | AZ36: 33833 | BA36: 1946 | BB36: 29309 | BC36: 8251 | BD36: 17240 | BE36: 157050 | BF36: 33833 | BG36: 1862 | BH36: 29309 | BI36: 8251 | BJ36: 0 | BK36: 156900 | BL36: 33833 | BM36: 1803 | BN36: 29309 | BO36: 8251 | BP36: 0 | BQ36: 145800 | BR36: 33833 | BS36: 2125 | BT36: 27541 | BU36: 8251 | BV36: 17240 | BW36: 154450 | BX36: 33833 | BY36: 1840 | BZ36: 27541 | CA36: 8251 | CB36: 0 | CC36: 153800 | CD36: 33833 | CE36: 1931 | CF36: 27541 | CG36: 8251 | CH36: 0
B37: 0 | C37: 職員 | D37: 1443 | E37: 松山 | F37: 透 | G37: 22 | H37: 職員 | I37: 6 | J37: ビル管理部 | K37: 6 | L37: 工事課 | M37: 41400 | N37: 商品原価 | O37: 288500 | P37: 59833 | Q37: 3628 | R37: 56840 | S37: 9576 | T37: 39340 | U37: 283400 | V37: 59833 | W37: 3290 | X37: 56840 | Y37: 9576 | Z37: 0 | AA37: 278500 | AB37: 59833 | AC37: 3298 | AD37: 56840 | AE37: 9576 | AF37: 0 | AG37: 286200 | AH37: 59833 | AI37: 3568 | AJ37: 56840 | AK37: 9576 | AL37: 39340 | AM37: 278500 | AN37: 59833 | AO37: 3267 | AP37: 56840 | AQ37: 9576 | AR37: 0 | AS37: 278500 | AT37: 59833 | AU37: 3195 | AV37: 56840 | AW37: 9576 | AX37: 0 | AY37: 286200 | AZ37: 59833 | BA37: 3568 | BB37: 54415 | BC37: 9576 | BD37: 39340 | BE37: 278500 | BF37: 59833 | BG37: 3267 | BH37: 54415 | BI37: 9576 | BJ37: 0 | BK37: 278500 | BL37: 59833 | BM37: 3195 | BN37: 54415 | BO37: 9576 | BP37: 0 | BQ37: 276500 | BR37: 59833 | BS37: 3863 | BT37: 56824 | BU37: 9576 | BV37: 39340 | BW37: 276500 | BX37: 59833 | BY37: 3450 | BZ37: 56824 | CA37: 9576 | CB37: 0 | CC37: 284800 | CD37: 59833 | CE37: 3450 | CF37: 56824 | CG37: 9576 | CH37: 0
B38: 0 | C38: 職員 | D38: 1460 | E38: 福地 | F38: 智之 | G38: 22 | H38: 職員 | I38: 6 | J38: ビル管理部 | K38: 6 | L38: 工事課 | M38: 41400 | N38: 商品原価 | O38: 206800 | P38: 48166 | Q38: 3078 | R38: 38118 | S38: 10679 | T38: 45390 | U38: 252600 | V38: 48166 | W38: 2402 | X38: 38118 | Y38: 10679 | Z38: 0 | AA38: 231400 | AB38: 48166 | AC38: 2885 | AD38: 38118 | AE38: 10679 | AF38: 0 | AG38: 226300 | AH38: 48166 | AI38: 3067 | AJ38: 38118 | AK38: 10679 | AL38: 45390 | AM38: 231600 | AN38: 48166 | AO38: 2588 | AP38: 38118 | AQ38: 10679 | AR38: 0 | AS38: 226600 | AT38: 48166 | AU38: 2638 | AV38: 38118 | AW38: 10679 | AX38: 0 | AY38: 243900 | AZ38: 48166 | BA38: 3149 | BB38: 44174 | BC38: 10679 | BD38: 45390 | BE38: 239800 | BF38: 48166 | BG38: 2754 | BH38: 44174 | BI38: 10679 | BJ38: 0 | BK38: 219600 | BL38: 48166 | BM38: 2716 | BN38: 44174 | BO38: 10679 | BP38: 0 | BQ38: 197400 | BR38: 48166 | BS38: 2984 | BT38: 38107 | BU38: 10679 | BV38: 45390 | BW38: 197400 | BX38: 48166 | BY38: 2509 | BZ38: 38107 | CA38: 10679 | CB38: 0 | CC38: 246600 | CD38: 48166 | CE38: 2729 | CF38: 38107 | CG38: 10679 | CH38: 0
B39: 0 | C39: 職員 | D39: 1471 | E39: 小林 | F39: 俊介 | G39: 22 | H39: 職員 | I39: 6 | J39: ビル管理部 | K39: 6 | L39: 工事課 | M39: 41400 | N39: 商品原価 | O39: 165900 | P39: 42166 | Q39: 2528 | R39: 31553 | S39: 7652 | T39: 43510 | U39: 197900 | V39: 42166 | W39: 1963 | X39: 31553 | Y39: 7652 | Z39: 0 | AA39: 188300 | AB39: 42166 | AC39: 2448 | AD39: 31553 | AE39: 7652 | AF39: 0 | AG39: 172300 | AH39: 42166 | AI39: 2588 | AJ39: 31553 | AK39: 7652 | AL39: 43510 | AM39: 180600 | AN39: 42166 | AO39: 2023 | AP39: 31553 | AQ39: 7652 | AR39: 0 | AS39: 180000 | AT39: 42166 | AU39: 2102 | AV39: 31553 | AW39: 7652 | AX39: 0 | AY39: 180600 | AZ39: 42166 | BA39: 2510 | BB39: 34705 | BC39: 7652 | BD39: 43510 | BE39: 180000 | BF39: 42166 | BG39: 2102 | BH39: 34705 | BI39: 7652 | BJ39: 0 | BK39: 187700 | BL39: 42166 | BM39: 2096 | BN39: 34705 | BO39: 7652 | BP39: 0 | BQ39: 165900 | BR39: 42166 | BS39: 2746 | BT39: 31544 | BU39: 7652 | BV39: 43510 | BW39: 165900 | BX39: 42166 | BY39: 2127 | BZ39: 31544 | CA39: 7652 | CB39: 0 | CC39: 181900 | CD39: 42166 | CE39: 2127 | CF39: 31544 | CG39: 7652 | CH39: 0
B40: 0 | C40: 職員 | D40: 1213 | E40: 伊東 | F40: 一典 | G40: 23 | H40: 嘱託 | I40: 6 | J40: ビル管理部 | K40: 6 | L40: 工事課 | M40: 41400 | N40: 商品原価 | O40: 312055 | P40: 0 | Q40: 3747 | R40: 50929 | S40: 0 | T40: 89490 | U40: 343283 | V40: 0 | W40: 2679 | X40: 50929 | Y40: 0 | Z40: 0 | AA40: 335225 | AB40: 0 | AC40: 3261 | AD40: 50929 | AE40: 0 | AF40: 0 | AG40: 332467 | AH40: 0 | AI40: 4034 | AJ40: 50929 | AK40: 0 | AL40: 89490 | AM40: 332467 | AN40: 0 | AO40: 3158 | AP40: 50929 | AQ40: 0 | AR40: 0 | AS40: 362495 | AT40: 0 | AU40: 3158 | AV40: 50929 | AW40: 0 | AX40: 0 | AY40: 359866 | AZ40: 0 | BA40: 4293 | BB40: 51530 | BC40: 0 | BD40: 89490 | BE40: 351553 | BF40: 0 | BG40: 3418 | BH40: 51530 | BI40: 0 | BJ40: 0 | BK40: 275000 | BL40: 0 | BM40: 3340 | BN40: 51530 | BO40: 0 | BP40: 0 | BQ40: 305000 | BR40: 0 | BS40: 4142 | BT40: 50912 | BU40: 0 | BV40: 89490 | BW40: 305000 | BX40: 0 | BY40: 3203 | BZ40: 50912 | CA40: 0 | CB40: 0 | CC40: 305000 | CD40: 0 | CE40: 3203 | CF40: 50912 | CG40: 0 | CH40: 0
...
