Workbook

Sheet Ｈ27年度末退職金
A1: 準職員（常勤）退職金について | G1: ※陳野原準職員退職月まで積立額：2ヶ月分＝2,800円
L2: 42460 | R2: =TODAY() -> 42730
A3: 氏 名 | B3: 退職金起算日 （入社日の１ヶ月後） （さぽーとさっぽろ加入者は２ヶ月後から） | C3: 月額 | D3: さぽーとさっぽろ退職金 | E3: 解約時積立 | F3: 解約時 | G3: さぽーとさっぽろ退職金 | H3: さぽーとさっぽろ解約時 | I3: ２７年度末 累計積立見合額 | J3: ２７年度末 | K3: ２７年度末 | L3: ２７年度末迄 | M3: 定年到達 | N3: 定年時 | O3: 定年時 | P3: 定年時 | Q3: 定年時 | R3: 備 考
C4: 積立額 | D4: 加入年月日 | E4: 通算見合額 | F4: 既支払額 | G4: 解約年月日 | H4: 通算積立期間 | J4: 支払想定額 | K4: 支給率 | L4: 通算積立期間 | M4: 年月日 | N4: 通算積立期間 | O4: 通算積立額 | P4: 支給率 | Q4: 支払退職金
A5: 市場 | B5: 41061 | C5: 1400 | D5: 41091 | E5: 25200 | F5: 24070 | G5: 41639 | H5: 1年6ヶ月 | I5: 63000 | J5: =I5*K5 -> 61922.7 | K5: 0.9829 | L5: =DATEDIF(B5,$L$2,"y")&"年"&DATEDIF(B5,$L$2,"ym")&"ヶ月" -> 3年9ヶ月 | P5: 1.0064 | Q5: =O5*P5-F5 -> -24070 | R5: 燃料部
A6: 吉 | B6: 41760 | C6: 1400 | D6: - | E6: - | F6: - | G6: - | H6: - | I6: 30800 | J6: =I6*K6 -> 29666.56 | K6: 0.9632 | L6: =DATEDIF(B6,$L$2,"y")&"年"&DATEDIF(B6,$L$2,"ym")&"ヶ月" -> 1年10ヶ月 | Q6: =O6*P6-F6 -> #VALUE! | R6: 倶知安福光営業所
A7: 川村 | B7: 42095 | C7: 1400 | D7: - | E7: - | F7: - | G7: - | H7: - | I7: 15400 | J7: =I7*K7 -> 14400.54 | K7: 0.9351 | L7: =DATEDIF(B7,$L$2,"y")&"年"&DATEDIF(B7,$L$2,"ym")&"ヶ月" -> 0年11ヶ月 | Q7: =O7*P7-F7 -> #VALUE! | R7: 小樽支店
A8: 中嶋 | B8: 42125 | C8: 1400 | D8: - | E8: - | F8: - | G8: - | H8: - | I8: 14000 | J8: =I8*K8 -> 12000.8 | K8: 0.8572 | L8: =DATEDIF(B8,$L$2,"y")&"年"&DATEDIF(B8,$L$2,"ym")&"ヶ月" -> 0年10ヶ月 | Q8: =O8*P8-F8 -> #VALUE! | R8: 函館支店
A9: 真坂 | B9: 42125 | C9: 1400 | D9: - | E9: - | F9: - | G9: - | H9: - | I9: 14000 | J9: =I9*K9 -> 13091.4 | K9: 0.9351 | L9: =DATEDIF(B9,$L$2,"y")&"年"&DATEDIF(B9,$L$2,"ym")&"ヶ月" -> 0年10ヶ月 | Q9: =O9*P9-F9 -> #VALUE! | R9: 燃料・資源
A11: 俵 | B11: 40664 | C11: 1400 | D11: 40695 | E11: 43400 | F11: 42350 | G11: 41639 | H11: 2年7ヶ月 | I11: 81200 | J11: =I11*K11 -> 80144.4 | K11: 0.987 | L11: =DATEDIF(B11,$L$2,"y")&"年"&DATEDIF(B11,$L$2,"ym")&"ヶ月" -> 4年10ヶ月 | M11: 42626 | N11: 5年4ヶ月 | O11: 94600 | P11: 0.9917 | Q11: =O11*P11-F11 -> 51464.82 | R11: 倉庫部札幌倉庫課
A12: 三品 | B12: 42217 | C12: 1400 | D12: - | E12: - | F12: - | G12: - | H12: - | I12: 9800 | J12: =I12*K12 -> 5345.9 | K12: 0.5455 | L12: =DATEDIF(B12,$L$2,"y")&"年"&DATEDIF(B12,$L$2,"ym")&"ヶ月" -> 0年7ヶ月 | R12: 倉庫部札幌倉庫課
A13: 木村 | B13: 42278 | C13: 1400 | D13: - | E13: - | F13: - | G13: - | H13: - | I13: 7000 | J13: =I13*K13 -> 2727.2 | K13: 0.3896 | L13: =DATEDIF(B13,$L$2,"y")&"年"&DATEDIF(B13,$L$2,"ym")&"ヶ月" -> 0年5ヶ月 | R13: 倉庫部石狩倉庫課
A15: 六渡 | B15: 39173 | C15: 3400 | D15: 39539 | E15: 123800 | F15: 122990 | G15: 41729 | H15: 6年0ヶ月 | I15: 209800 | J15: =I15*K15 -> 209925.88 | K15: 1.0006 | L15: =DATEDIF(B15,$L$2,"y")&"年"&DATEDIF(B15,$L$2,"ym")&"ヶ月" -> 8年11ヶ月 | M15: 43097 | N15: 9年9ヶ月 | O15: 244550 | P15: 1.0028 | Q15: =O15*P15-F15 -> 122244.74 | R15: 福井砕石所
A16: 高森 | B16: 38108 | C16: 4400 | D16: 38139 | E16: 247200 | F16: 249190 | G16: 41729 | H16: 9年10ヶ月 | I16: 351800 | J16: =I16*K16 -> 355106.92 | K16: 1.0094 | L16: =DATEDIF(B16,$L$2,"y")&"年"&DATEDIF(B16,$L$2,"ym")&"ヶ月" -> 11年10ヶ月 | M16: 42765 | N16: 12年8ヶ月 | O16: 395800 | P16: 1.012 | Q16: =O16*P16-F16 -> 151359.6 | R16: 福井砕石所
A17: 坂口 | B17: 38473 | C17: 4400 | D17: 38504 | E17: 206400 | F17: 207300 | G17: 41729 | H17: 8年10ヶ月 | I17: 299000 | J17: =I17*K17 -> 300853.8 | K17: 1.0062 | L17: =DATEDIF(B17,$L$2,"y")&"年"&DATEDIF(B17,$L$2,"ym")&"ヶ月" -> 10年10ヶ月 | Q17: =O17*P17-F17 -> -207300 | R17: 福井砕石所
A18: 三上 | B18: 38473 | C18: 4400 | D18: 38504 | E18: 206400 | F18: 207300 | G18: 41729 | H18: 8年10ヶ月 | I18: 299000 | J18: =I18*K18 -> 300853.8 | K18: 1.0062 | L18: =DATEDIF(B18,$L$2,"y")&"年"&DATEDIF(B18,$L$2,"ym")&"ヶ月" -> 10年10ヶ月 | Q18: =O18*P18-F18 -> -207300 | R18: 福井砕石所
A19: 奥井 | B19: 41030 | C19: 1400 | D19: 41061 | E19: 30800 | F19: 29680 | G19: 41729 | H19: 1年10ヶ月 | I19: 64400 | J19: =I19*K19 -> 63330.96 | K19: 0.9834 | L19: =DATEDIF(B19,$L$2,"y")&"年"&DATEDIF(B19,$L$2,"ym")&"ヶ月" -> 3年10ヶ月 | P19: 1.0062 | Q19: =O19*P19-F19 -> -29680 | R19: 福井砕石所
A20: 竹井 | B20: 41030 | C20: 1400 | D20: 41061 | E20: 30800 | F20: 29680 | G20: 41729 | H20: 1年10ヶ月 | I20: 64400 | J20: =I20*K20 -> 63330.96 | K20: 0.9834 | L20: =DATEDIF(B20,$L$2,"y")&"年"&DATEDIF(B20,$L$2,"ym")&"ヶ月" -> 3年10ヶ月 | Q20: =O20*P20-F20 -> -29680 | R20: 福井砕石所
A21: 佐々木 | B21: 41944 | C21: 1400 | D21: - | E21: - | F21: - | G21: - | H21: - | I21: 22400 | J21: =I21*K21 -> 21174.72 | K21: 0.9453 | L21: =DATEDIF(B21,$L$2,"y")&"年"&DATEDIF(B21,$L$2,"ym")&"ヶ月" -> 1年4ヶ月 | Q21: =O21*P21-F21 -> #VALUE! | R21: 福井砕石所
A22: 堀井 | B22: 42186 | C22: 1400 | D22: - | E22: - | F22: - | G22: - | H22: - | I22: 11200 | J22: =I22*K22 -> 6982.08 | K22: 0.6234 | L22: =DATEDIF(B22,$L$2,"y")&"年"&DATEDIF(B22,$L$2,"ym")&"ヶ月" -> 0年8ヶ月 | Q22: =O22*P22-F22 -> #VALUE! | R22: 福井砕石所
A23: 澤口 | B23: 42278 | D23: - | E23: - | F23: - | G23: - | H23: - | I23: 7000 | J23: =I23*K23 -> 2727.2 | K23: 0.3896 | L23: =DATEDIF(B23,$L$2,"y")&"年"&DATEDIF(B23,$L$2,"ym")&"ヶ月" -> 0年5ヶ月 | Q23: =O23*P23-F23 -> #VALUE! | R23: 福井砕石所
A24: 岩崎 | B24: 42309 | D24: - | E24: - | F24: - | G24: - | H24: - | I24: 5600 | J24: =I24*K24 -> 1745.52 | K24: 0.3117 | L24: =DATEDIF(B24,$L$2,"y")&"年"&DATEDIF(B24,$L$2,"ym")&"ヶ月" -> 0年4ヶ月 | Q24: =O24*P24-F24 -> #VALUE! | R24: 釧路支社営業部
A25: 計18名 | F25: =SUM(F5:F22) -> 912560 | I25: =SUM(I5:I24) -> 1569800 | J25: =SUM(J5:J24) -> 1545331.3
H26: 27年度伸び額 | I26: =I25-#REF! -> #REF!
B27: 1年0ヶ月 | C27: =1400*12 -> 16800
B28: 2年0ヶ月 | C28: =1400*24 -> 33600 | E28: 月額掛金見合額 | I28: 定年到達時勤続年月 | K28: 定年到達時 | L28: A年 | M28: A＋1年 | N28: A年 | P28: 定年到達時 | Q28: さぽーとさっぽろ | R28: 定年到達時
B29: 3年0ヶ月 | C29: =1400*36 -> 50400 | E29: １，４００円 | G29: 0年1ヶ月～4年11ヶ月 | I29: A年 | J29: B箇月 | K29: 支給額 | L29: 支給額 | M29: 支給額 | N29: 支給額 | O29: B箇月 | P29: 支給率 | Q29: 解約時支払済額 | R29: 差引支給額
B30: 4年0ヶ月 | C30: =1400*48 -> 67200 | E30: ２，４００円 | G30: 5年0ヶ月～7年11ヶ月 | H30: 川村 | I30: 1 | J30: 10 | K30: =(L30+((M30-N30)*O30/12))*P30 -> 46467.12 | L30: 33600 | M30: 50400 | N30: 33600 | O30: 10 | P30: 0.9762 | Q30: 22640 | R30: =K30-Q30 -> 23827.12
B31: 4年11ヶ月 | C31: =C30+(1400*11) -> 82600 | E31: ３，４００円 | G31: 8年0ヶ月～9年11ヶ月 | H31: 俵 | I31: 5 | J31: 4 | K31: =(L31+((M31-N31)*O31/12))*P31 -> 93814.82 | L31: 85000 | M31: 113800 | N31: 85000 | O31: 4 | P31: 0.9917 | Q31: 42350 | R31: =K31-Q31 -> 51464.82
B32: 5年0ヶ月 | C32: =C31+2400 -> 85000 | E32: ４，４００円 | G32: 10年0ヶ月～ | H32: 高森 | I32: 12 | J32: 8 | K32: =(L32+((M32-N32)*O32/12))*P32 -> 400549.6 | L32: 360600 | M32: 413400 | N32: 360600 | O32: 8 | P32: 1.012 | Q32: 249190 | R32: =K32-Q32 -> 151359.6
B33: 6年0ヶ月 | C33: =C32+2400*12 -> 113800 | H33: 六渡 | I33: 9 | J33: 9 | K33: =(L33+((M33-N33)*O33/12))*P33 -> 245234.74 | L33: 213200 | M33: 255000 | N33: 213200 | O33: 9 | P33: 1.0028 | Q33: 122990 | R33: =K33-Q33 -> 122244.74
B34: 7年0ヶ月 | C34: =C33+2400*12 -> 142600 | D34: 勤続期間 | E34: 年間積立額 | H34: 真坂 | I34: 5 | J34: 10 | K34: =(L34+((M34-N34)*O34/12))*P34 -> 108771.1 | L34: 85000 | M34: 113800 | N34: 85000 | O34: 10 | P34: 0.9979 | Q34: 0 | R34: =K34-Q34 -> 108771.1
B35: 7年11ヶ月 | C35: =C34+2400*11 -> 169000 | D35: 0年1ヶ月～4年11ヶ月 | E35: =1400*12 -> 16800 | H35: 市場 | I35: 10 | J35: 11 | K35: =(L35+((M35-N35)*O35/12))*P35 -> 305341.76 | L35: 255000 | M35: 307800 | N35: 255000 | O35: 11 | P35: 1.0064 | Q35: 24070 | R35: =K35-Q35 -> 281271.76
B36: 8年0ヶ月 | C36: =C35+3400 -> 172400 | D36: 5年0ヶ月～7年11ヶ月 | E36: =2400*12 -> 28800 | H36: 奥井 | I36: 10 | J36: 10 | K36: =(L36+((M36-N36)*O36/12))*P36 -> 300853.8 | L36: 255000 | M36: 307800 | N36: 255000 | O36: 10 | P36: 1.0062 | Q36: 26980 | R36: =K36-Q36 -> 273873.8
B37: 9年0ヶ月 | C37: =C36+3400*12 -> 213200 | D37: 8年0ヶ月～9年11ヶ月 | E37: =3400*12 -> 40800 | I37: 積立額に対する支給率は従前加入の公益財団法人札幌市中小企業共済センター特定退職金共済制度に因る。
B38: 9年11ヶ月 | C38: =C37+3400*11 -> 250600 | D38: 10年0ヶ月～ | E38: =4400*12 -> 52800 | I38: 勤続年数（さぽーとさっぽろ加入対象者については、加入期間）に年未満の端数月数があるときは、次の月割計算を行う。
B39: 10年0ヶ月 | C39: =C38+4400 -> 255000 | I39: A年Bヶ月の支給額＝{Ａ年の支給額＋{（Ａ＋１年の支給額－Ａ年の支給額）×Ｂ÷１２｝}×支給率
B40: 11年0ヶ月 | C40: =C39+4400*12 -> 307800 | I40: 支給額に円未満の端数がある場合は四捨五入する。
B41: 12年0ヶ月 | C41: =C40+4400*12 -> 360600 | I41: 支給率についても端数月がある場合は同様に端数計算をし、当該月の支給率を算出する。
B42: 13年0ヶ月 | C42: =C41+4400*12 -> 413400
...

Sheet Ｈ28年度末退職金
A1: 準職員（常勤）退職金について | G1: →定年到達者
G2: →自己都合等退職者 | L2: 42825 | R2: =TODAY() -> 42730
A3: 氏 名 | B3: 退職金起算日 （入社日の１ヶ月後） （さぽーとさっぽろ加入者は２ヶ月後から） | C3: 月額 | D3: さぽーとさっぽろ退職金 | E3: 解約時積立 | F3: 解約時 | G3: さぽーとさっぽろ退職金 | H3: さぽーとさっぽろ解約時 | I3: ２８年度末 累計積立見合額 | J3: ２８年度末 | K3: ２８年度末 | L3: ２８年度末迄 | M3: 定年到達 | N3: 定年時 | O3: 定年時 | P3: 定年時 | Q3: 定年時 | R3: 備 考
C4: 積立額 | D4: 加入年月日 | E4: 通算見合額 | F4: 既支払額 | G4: 解約年月日 | H4: 通算積立期間 | J4: 支払想定額 | K4: 支給率 | L4: 通算積立期間 | M4: 年月日 | N4: 通算積立期間 | O4: 通算積立額 | P4: 支給率 | Q4: 支払退職金
A5: 市場 | B5: 41061 | C5: 1400 | D5: 41091 | E5: 25200 | F5: 24070 | G5: 41639 | H5: 1年6ヶ月 | I5: 79800 | J5: =I5*K5 -> 78738.66 | K5: 0.9867 | L5: =DATEDIF(B5,$L$2,"y")&"年"&DATEDIF(B5,$L$2,"ym")&"ヶ月" -> 4年9ヶ月 | Q5: =O5*P5-F5 -> -24070 | R5: 燃料部
A6: 吉 | B6: 41760 | C6: 1400 | D6: - | E6: - | F6: - | G6: - | H6: - | I6: 47600 | J6: =I6*K6 -> 46467.12 | K6: 0.9762 | L6: =DATEDIF(B6,$L$2,"y")&"年"&DATEDIF(B6,$L$2,"ym")&"ヶ月" -> 2年10ヶ月 | Q6: =O6*P6-F6 -> #VALUE! | R6: 倶知安福光営業所
A7: 川村 | B7: 42095 | C7: 1400 | D7: - | E7: - | F7: - | G7: - | H7: - | I7: 19600 | J7: =I7*K7+180000 -> 198427.92 | K7: 0.9402 | L7: =DATEDIF(B7,$L$2,"y")&"年"&DATEDIF(B7,$L$2,"ym")&"ヶ月" -> 1年11ヶ月 | Q7: =O7*P7-F7 -> #VALUE! | R7: 小樽支店
A8: 佐藤裕 | B8: 42125 | C8: 1400 | D8: - | E8: - | F8: - | G8: - | H8: - | I8: 30800 | J8: =I8*K8 -> 29589.56 | K8: 0.9607 | L8: =DATEDIF(B8,$L$2,"y")&"年"&DATEDIF(B8,$L$2,"ym")&"ヶ月" -> 1年10ヶ月 | Q8: =O8*P8-F8 -> #VALUE! | R8: 函館支店
A9: 真坂 | B9: 42125 | C9: 1400 | D9: - | E9: - | F9: - | G9: - | H9: - | I9: 30800 | J9: =I9*K9 -> 29589.56 | K9: 0.9607 | L9: =DATEDIF(B9,$L$2,"y")&"年"&DATEDIF(B9,$L$2,"ym")&"ヶ月" -> 1年10ヶ月 | Q9: =O9*P9-F9 -> #VALUE! | R9: 燃料・資源
A11: 俵 | B11: 40664 | C11: 1400 | D11: 40695 | E11: 43400 | F11: 42350 | G11: 41639 | H11: 2年7ヶ月 | I11: 94600 | J11: =I11*K11 -> 93814.82 | K11: 0.9917 | L11: 5年4ヶ月 | M11: 42626 | N11: 5年4ヶ月 | O11: 94600 | P11: 0.9917 | Q11: =O11*P11-F11 -> 51464.82 | R11: 倉庫部札幌倉庫課
A13: 六渡 | B13: 39173 | C13: 3400 | D13: 39539 | E13: 123800 | F13: 122990 | G13: 41729 | H13: 6年0ヶ月 | I13: 250600 | J13: =I13*K13 -> 251401.92 | K13: 1.0032 | L13: =DATEDIF(B13,$L$2,"y")&"年"&DATEDIF(B13,$L$2,"ym")&"ヶ月" -> 9年11ヶ月 | Q13: =O13*P13-F13 -> -122990 | R13: 資源部福井砕石所
A14: 高森 | B14: 38108 | C14: 4400 | D14: 38139 | E14: 247200 | F14: 249190 | G14: 41729 | H14: 9年10ヶ月 | I14: 395800 | J14: =I14*K14 -> 400549.6 | K14: 1.012 | L14: 12年8ヶ月 | M14: 42765 | N14: 12年8ヶ月 | O14: 395800 | P14: 1.012 | Q14: =O14*P14-F14 -> 151359.6 | R14: 資源部福井砕石所
A15: 坂口 | B15: 38473 | C15: 4400 | D15: 38504 | E15: 206400 | F15: 207300 | G15: 41729 | H15: 8年10ヶ月 | I15: 351800 | J15: =I15*K15 -> 355106.92 | K15: 1.0094 | L15: =DATEDIF(B15,$L$2,"y")&"年"&DATEDIF(B15,$L$2,"ym")&"ヶ月" -> 11年10ヶ月 | Q15: =O15*P15-F15 -> -207300 | R15: 資源部福井砕石所
A16: 三上 | B16: 38473 | C16: 4400 | D16: 38504 | E16: 206400 | F16: 207300 | G16: 41729 | H16: 8年10ヶ月 | I16: 351800 | J16: =I16*K16 -> 355106.92 | K16: 1.0094 | L16: =DATEDIF(B16,$L$2,"y")&"年"&DATEDIF(B16,$L$2,"ym")&"ヶ月" -> 11年10ヶ月 | Q16: =O16*P16-F16 -> -207300 | R16: 資源部福井砕石所
A17: 奥井 | B17: 41030 | C17: 1400 | D17: 41061 | E17: 30800 | F17: 29680 | G17: 41729 | H17: 1年10ヶ月 | I17: 81200 | J17: =I17*K17 -> 80144.4 | K17: 0.987 | L17: =DATEDIF(B17,$L$2,"y")&"年"&DATEDIF(B17,$L$2,"ym")&"ヶ月" -> 4年10ヶ月 | Q17: =O17*P17-F17 -> -29680 | R17: 資源部福井砕石所
A18: 竹井 | B18: 41030 | C18: 1400 | D18: 41061 | E18: 30800 | F18: 29680 | G18: 41729 | H18: 1年10ヶ月 | I18: 81200 | J18: =I18*K18 -> 80144.4 | K18: 0.987 | L18: =DATEDIF(B18,$L$2,"y")&"年"&DATEDIF(B18,$L$2,"ym")&"ヶ月" -> 4年10ヶ月 | Q18: =O18*P18-F18 -> -29680 | R18: 資源部福井砕石所
A19: 佐々木和 | B19: 41944 | C19: 1400 | D19: - | E19: - | F19: - | G19: - | H19: - | I19: 39200 | J19: =I19*K19 -> 38024 | K19: 0.97 | L19: =DATEDIF(B19,$L$2,"y")&"年"&DATEDIF(B19,$L$2,"ym")&"ヶ月" -> 2年4ヶ月 | Q19: =O19*P19-F19 -> #VALUE! | R19: 資源部福井砕石所
A20: 堀井 | B20: 42186 | C20: 1400 | D20: - | E20: - | F20: - | G20: - | H20: - | I20: 19600 | J20: =I20*K20 -> 18427.92 | K20: 0.9402 | L20: =DATEDIF(B20,$L$2,"y")&"年"&DATEDIF(B20,$L$2,"ym")&"ヶ月" -> 1年8ヶ月 | Q20: =O20*P20-F20 -> #VALUE! | R20: 資源部福井砕石所
A21: 澤口 | B21: 42278 | D21: - | E21: - | F21: - | G21: - | H21: - | I21: 23800 | J21: =I21*K21 -> 22560.02 | K21: 0.9479 | L21: =DATEDIF(B21,$L$2,"y")&"年"&DATEDIF(B21,$L$2,"ym")&"ヶ月" -> 1年5ヶ月 | Q21: =O21*P21-F21 -> #VALUE! | R21: 資源部福井砕石所
A22: 蠟山 | B22: 42491 | D22: - | E22: - | F22: - | G22: - | H22: - | I22: 14000 | J22: =I22*K22 -> 10910.2 | K22: 0.7793 | L22: =DATEDIF(B22,$L$2,"y")&"年"&DATEDIF(B22,$L$2,"ym")&"ヶ月" -> 0年10ヶ月 | R22: 倉庫部釧路倉庫課
A23: 赤枝 | B23: 42522 | D23: - | E23: - | F23: - | G23: - | H23: - | I23: 2800 | J23: 2800 | K23: - | L23: =DATEDIF(B23,$L$2,"y")&"年"&DATEDIF(B23,$L$2,"ym")&"ヶ月" -> 0年9ヶ月 | R23: 倉庫部札幌倉庫課
A24: 引田 | B24: 42522 | D24: - | E24: - | F24: - | G24: - | H24: - | I24: 12600 | J24: =I24*K24 -> 8836.38 | K24: 0.7013 | L24: =DATEDIF(B24,$L$2,"y")&"年"&DATEDIF(B24,$L$2,"ym")&"ヶ月" -> 0年9ヶ月 | R24: 資源部美唄炭砿
A25: 古村 | B25: 42552 | D25: - | E25: - | F25: - | G25: - | H25: - | I25: 11200 | J25: =I25*K25 -> 6982.08 | K25: 0.6234 | L25: =DATEDIF(B25,$L$2,"y")&"年"&DATEDIF(B25,$L$2,"ym")&"ヶ月" -> 0年8ヶ月 | R25: 倉庫部石狩倉庫課
A26: 佐々木幸 | B26: 42552 | D26: - | E26: - | F26: - | G26: - | H26: - | I26: 11200 | J26: =I26*K26 -> 6982.08 | K26: 0.6234 | L26: =DATEDIF(B26,$L$2,"y")&"年"&DATEDIF(B26,$L$2,"ym")&"ヶ月" -> 0年8ヶ月 | R26: 資源部美唄炭砿
A27: 田中隆 | B27: 42675 | D27: - | E27: - | F27: - | G27: - | H27: - | I27: 5600 | J27: =I27*K27 -> 1745.52 | K27: 0.3117 | L27: =DATEDIF(B27,$L$2,"y")&"年"&DATEDIF(B27,$L$2,"ym")&"ヶ月" -> 0年4ヶ月 | R27: 資源部管理課
A28: 佐藤路 | B28: 42675 | D28: - | E28: - | F28: - | G28: - | H28: - | I28: 5600 | J28: =I28*K28 -> 1745.52 | K28: 0.3117 | L28: =DATEDIF(B28,$L$2,"y")&"年"&DATEDIF(B28,$L$2,"ym")&"ヶ月" -> 0年4ヶ月 | R28: 倉庫部釧路倉庫課
A29: 玉田 | B29: 42705 | D29: - | E29: - | F29: - | G29: - | H29: - | I29: 4200 | J29: =I29*K29 -> 981.96 | K29: 0.2338 | L29: =DATEDIF(B29,$L$2,"y")&"年"&DATEDIF(B29,$L$2,"ym")&"ヶ月" -> 0年3ヶ月 | R29: 倉庫部釧路倉庫課
A34: 計22名 | F34: =SUM(F5:F33) -> 912560 | I34: =SUM(I5:I33) -> 1965400 | J34: =SUM(J5:J33) -> 2119077.5
H35: 28年度伸び額 | I35: =I34-Ｈ27年度末退職金!I25 -> 395600 | J35: =J34-Ｈ27年度末退職金!J25 -> 573746.14
I37: 定年到達時勤続年月 | K37: 定年到達時 | L37: A年 | M37: A＋1年 | N37: A年 | P37: 定年到達時 | Q37: さぽーとさっぽろ | R37: 定年到達時
I38: A年 | J38: B箇月 | K38: 支給額 | L38: 支給額 | M38: 支給額 | N38: 支給額 | O38: B箇月 | P38: 支給率 | Q38: 解約時支払済額 | R38: 差引支給額
H39: 俵 | I39: 5 | J39: 4 | K39: =(L39+((M39-N39)*O39/12))*P39 -> 93814.82 | L39: 85000 | M39: 113800 | N39: 85000 | O39: 4 | P39: 0.9917 | Q39: 42350 | R39: =K39-Q39 -> 51464.82
H40: 高森 | I40: 12 | J40: 8 | K40: =(L40+((M40-N40)*O40/12))*P40 -> 400549.6 | L40: 360600 | M40: 413400 | N40: 360600 | O40: 8 | P40: 1.012 | Q40: 249190 | R40: =K40-Q40 -> 151359.6
I41: 積立額に対する支給率は従前加入の公益財団法人札幌市中小企業共済センター特定退職金共済制度に因る。
I42: 勤続年数（さぽーとさっぽろ加入対象者については、加入期間）に年未満の端数月数があるときは、次の月割計算を行う。
I43: A年Bヶ月の支給額＝{Ａ年の支給額＋{（Ａ＋１年の支給額－Ａ年の支給額）×Ｂ÷１２｝}×支給率
I44: 支給額に円未満の端数がある場合は四捨五入する。
I45: 支給率についても端数月がある場合は同様に端数計算をし、当該月の支給率を算出する。
I46: 俵準職員の定年到達は平成28年9月13日。退職金支給額の計算を行う。
I47: 高森準職員の定年到達は平成29年1月30日。退職金支給額の計算を行う。
...

Sheet Ｈ29年度末退職金
A1: 準職員（常勤）退職金について | G1: →定年到達者
G2: →自己都合等退職者 | L2: 43190 | R2: =TODAY() -> 42730
A3: 氏 名 | B3: 退職金起算日 （入社日の１ヶ月後） （さぽーとさっぽろ加入者は２ヶ月後から） | C3: 月額 | D3: さぽーとさっぽろ退職金 | E3: 解約時積立 | F3: 解約時 | G3: さぽーとさっぽろ退職金 | H3: さぽーとさっぽろ解約時 | I3: ２９年度末 累計積立見合額 | J3: ２９年度末 | K3: ２９年度末 | L3: ２９年度末迄 | M3: 定年到達 | N3: 定年時 | O3: 定年時 | P3: 定年時 | Q3: 定年時 | R3: 備 考
C4: 積立額 | D4: 加入年月日 | E4: 通算見合額 | F4: 既支払額 | G4: 解約年月日 | H4: 通算積立期間 | J4: 支払想定額 | K4: 支給率 | L4: 通算積立期間 | M4: 年月日 | N4: 通算積立期間 | O4: 通算積立額 | P4: 支給率 | Q4: 支払退職金
A5: 市場 | B5: 41061 | C5: 1400 | D5: 41091 | E5: 25200 | F5: 24070 | G5: 41639 | H5: 1年6ヶ月 | I5: 106600 | J5: =I5*K5 -> 106269.54 | K5: 0.9969 | L5: =DATEDIF(B5,$L$2,"y")&"年"&DATEDIF(B5,$L$2,"ym")&"ヶ月" -> 5年9ヶ月 | P5: 1.0064 | Q5: =O5*P5-F5 -> -24070 | R5: 燃料部
A6: 吉 | B6: 41760 | C6: 1400 | D6: - | E6: - | F6: - | G6: - | H6: - | I6: 64400 | J6: =I6*K6 -> 63330.96 | K6: 0.9834 | L6: =DATEDIF(B6,$L$2,"y")&"年"&DATEDIF(B6,$L$2,"ym")&"ヶ月" -> 3年10ヶ月 | Q6: =O6*P6-F6 -> #VALUE! | R6: 倶知安福光営業所
A7: 佐藤裕 | B7: 42125 | C7: 1400 | D7: - | E7: - | F7: - | G7: - | H7: - | I7: 47600 | J7: =I7*K7 -> 46467.12 | K7: 0.9762 | L7: =DATEDIF(B7,$L$2,"y")&"年"&DATEDIF(B7,$L$2,"ym")&"ヶ月" -> 2年10ヶ月 | Q7: =O7*P7-F7 -> #VALUE! | R7: 函館支店
A8: 真坂 | B8: 42125 | C8: 1400 | D8: - | E8: - | F8: - | G8: - | H8: - | I8: 47600 | J8: =I8*K8 -> 46467.12 | K8: 0.9762 | L8: =DATEDIF(B8,$L$2,"y")&"年"&DATEDIF(B8,$L$2,"ym")&"ヶ月" -> 2年10ヶ月 | Q8: =O8*P8-F8 -> #VALUE! | R8: 燃料・資源
A11: 六渡 | B11: 39173 | C11: 3400 | D11: 39539 | E11: 123800 | F11: 122990 | G11: 41729 | H11: 6年0ヶ月 | I11: 290200 | J11: =I11*K11 -> 291825.12 | K11: 1.0056 | L11: =DATEDIF(B11,$M$11,"y")&"年"&DATEDIF(B11,$M$11,"ym")&"ヶ月" -> 10年8ヶ月 | M11: 43097 | P11: 1.0056 | Q11: =O11*P11-F11 -> -122990 | R11: 福井砕石所
A12: 坂口 | B12: 38473 | C12: 4400 | D12: 38504 | E12: 206400 | F12: 207300 | G12: 41729 | H12: 8年10ヶ月 | I12: 404600 | J12: =I12*K12 -> 409697.96 | K12: 1.0126 | L12: =DATEDIF(B12,$L$2,"y")&"年"&DATEDIF(B12,$L$2,"ym")&"ヶ月" -> 12年10ヶ月 | Q12: =O12*P12-F12 -> -207300 | R12: 福井砕石所
A13: 三上 | B13: 38473 | C13: 4400 | D13: 38504 | E13: 206400 | F13: 207300 | G13: 41729 | H13: 8年10ヶ月 | I13: 404600 | J13: =I13*K13 -> 409697.96 | K13: 1.0126 | L13: =DATEDIF(B13,$L$2,"y")&"年"&DATEDIF(B13,$L$2,"ym")&"ヶ月" -> 12年10ヶ月 | Q13: =O13*P13-F13 -> -207300 | R13: 福井砕石所
A14: 奥井 | B14: 41030 | C14: 1400 | D14: 41061 | E14: 30800 | F14: 29680 | G14: 41729 | H14: 1年10ヶ月 | I14: 109000 | J14: =I14*K14 -> 108771.1 | K14: 0.9979 | L14: =DATEDIF(B14,$L$2,"y")&"年"&DATEDIF(B14,$L$2,"ym")&"ヶ月" -> 5年10ヶ月 | P14: 1.0062 | Q14: =O14*P14-F14 -> -29680 | R14: 福井砕石所
A15: 竹井 | B15: 41030 | C15: 1400 | D15: 41061 | E15: 30800 | F15: 29680 | G15: 41729 | H15: 1年10ヶ月 | I15: 109000 | J15: =I15*K15 -> 108771.1 | K15: 0.9979 | L15: =DATEDIF(B15,$L$2,"y")&"年"&DATEDIF(B15,$L$2,"ym")&"ヶ月" -> 5年10ヶ月 | Q15: =O15*P15-F15 -> -29680 | R15: 福井砕石所
A16: 佐々木和 | B16: 41944 | C16: 1400 | D16: - | E16: - | F16: - | G16: - | H16: - | I16: 56000 | J16: =I16*K16 -> 54896.8 | K16: 0.9803 | L16: =DATEDIF(B16,$L$2,"y")&"年"&DATEDIF(B16,$L$2,"ym")&"ヶ月" -> 3年4ヶ月 | Q16: =O16*P16-F16 -> #VALUE! | R16: 福井砕石所
A17: 澤口 | B17: 42278 | D17: - | E17: - | F17: - | G17: - | H17: - | I17: 40600 | J17: =I17*K17 -> 39422.6 | K17: 0.971 | L17: =DATEDIF(B17,$L$2,"y")&"年"&DATEDIF(B17,$L$2,"ym")&"ヶ月" -> 2年5ヶ月 | Q17: =O17*P17-F17 -> #VALUE! | R17: 福井砕石所
A18: 蠟山 | B18: 42491 | D18: - | E18: - | F18: - | G18: - | H18: - | I18: 30800 | J18: =I18*K18 -> 29589.56 | K18: 0.9607 | L18: =DATEDIF(B18,$L$2,"y")&"年"&DATEDIF(B18,$L$2,"ym")&"ヶ月" -> 1年10ヶ月 | R18: 倉庫部釧路倉庫課
A19: 引田 | B19: 42522 | D19: - | E19: - | F19: - | G19: - | H19: - | I19: 29400 | J19: =I19*K19 -> 28168.14 | K19: 0.9581 | L19: =DATEDIF(B19,$L$2,"y")&"年"&DATEDIF(B19,$L$2,"ym")&"ヶ月" -> 1年9ヶ月 | R19: 資源部美唄炭砿
A20: 古村 | B20: 42552 | D20: - | E20: - | F20: - | G20: - | H20: - | I20: 28000 | J20: =I20*K20 -> 26756.8 | K20: 0.9556 | L20: =DATEDIF(B20,$L$2,"y")&"年"&DATEDIF(B20,$L$2,"ym")&"ヶ月" -> 1年8ヶ月 | R20: 倉庫部石狩倉庫課
A21: 佐々木幸 | B21: 42552 | D21: - | E21: - | F21: - | G21: - | H21: - | I21: 28000 | J21: =I21*K21 -> 26756.8 | K21: 0.9556 | L21: =DATEDIF(B21,$L$2,"y")&"年"&DATEDIF(B21,$L$2,"ym")&"ヶ月" -> 1年8ヶ月 | R21: 資源部美唄炭砿
A22: 田中隆 | B22: 42675 | D22: - | E22: - | F22: - | G22: - | H22: - | I22: 22400 | J22: =I22*K22 -> 21174.72 | K22: 0.9453 | L22: =DATEDIF(B22,$L$2,"y")&"年"&DATEDIF(B22,$L$2,"ym")&"ヶ月" -> 1年4ヶ月 | R22: 資源部管理課
A23: 佐藤路 | B23: 42675 | D23: - | E23: - | F23: - | G23: - | H23: - | I23: 22400 | J23: =I23*K23 -> 21174.72 | K23: 0.9453 | L23: =DATEDIF(B23,$L$2,"y")&"年"&DATEDIF(B23,$L$2,"ym")&"ヶ月" -> 1年4ヶ月 | R23: 倉庫部釧路倉庫課
A24: 玉田 | B24: 42705 | D24: - | E24: - | F24: - | G24: - | H24: - | I24: 21000 | J24: =I24*K24 -> 19798.8 | K24: 0.9428 | L24: =DATEDIF(B24,$L$2,"y")&"年"&DATEDIF(B24,$L$2,"ym")&"ヶ月" -> 1年3ヶ月 | R24: 倉庫部釧路倉庫課
A29: 計18名 | F29: =SUM(F5:F28) -> 621020 | I29: =SUM(I5:I28) -> 1862200 | J29: =SUM(J5:J28) -> 1859036.9
H30: 29年度伸び額 | I30: =I29-Ｈ28年度末退職金!I34 -> -103200 | J30: =J29-Ｈ28年度末退職金!J34 -> -260040.56
I32: 定年到達時勤続年月 | K32: 定年到達時 | L32: A年 | M32: A＋1年 | N32: A年 | P32: 定年到達時 | Q32: さぽーとさっぽろ | R32: 定年到達時
I33: A年 | J33: B箇月 | K33: 支給額 | L33: 支給額 | M33: 支給額 | N33: 支給額 | O33: B箇月 | P33: 支給率 | Q33: 解約時支払済額 | R33: 差引支給額
H34: 六渡 | I34: 10 | J34: 8 | K34: =(L34+((M34-N34)*O34/12))*P34 -> 291825.12 | L34: 255000 | M34: 307800 | N34: 255000 | O34: 8 | P34: 1.0056 | Q34: 122990 | R34: =K34-Q34 -> 168835.12
I35: 積立額に対する支給率は従前加入の公益財団法人札幌市中小企業共済センター特定退職金共済制度に因る。
I36: 勤続年数（さぽーとさっぽろ加入対象者については、加入期間）に年未満の端数月数があるときは、次の月割計算を行う。
I37: A年Bヶ月の支給額＝{Ａ年の支給額＋{（Ａ＋１年の支給額－Ａ年の支給額）×Ｂ÷１２｝}×支給率
I38: 支給額に円未満の端数がある場合は四捨五入する。
I39: 支給率についても端数月がある場合は同様に端数計算をし、当該月の支給率を算出する。
I40: 六渡準職員の定年到達は平成29年12月28日。退職金支給額の計算を行う。
C44: =C43+4400*12 -> 52800
C45: =C44+4400*12 -> 105600
C46: =C45+4400*12 -> 158400
C47: =C46+4400*12 -> 211200
C48: =C47+4400*12 -> 264000

Sheet H28-H29対比
A1: 準職員（常勤）退職金期末額 対比 | G1: →定年到達者 | AA1: →定年到達者
G2: →自己都合退職者 | L2: 42825 | R2: =TODAY() -> 42730 | AA2: →自己都合退職者 | AD2: 印刷日： | AF2: 43190 | AL2: =TODAY() -> 42730 | AO2: 予算用H28-H29伸び額
A3: 氏 名 | B3: 退職金起算日 （入社日の１ヶ月後） （さぽーとさっぽろ加入者は２ヶ月後から） | C3: 月額 | D3: さぽーとさっぽろ退職金 | E3: 解約時積立 | F3: 解約時 | G3: さぽーとさっぽろ退職金 | H3: さぽーとさっぽろ解約時 | I3: ２８年度末 累計積立 見合額 | J3: ２８年度末 | K3: ２８年度末 | L3: ２８年度末迄 | M3: 定年到達 | N3: 定年時 | O3: 定年時 | P3: 定年時 | Q3: 定年時 | R3: 備 考 | U3: 氏 名 | V3: 退職金起算日 （入社日の１ヶ月後） （さぽーとさっぽろ加入者は２ヶ月後から） | W3: 月額 | X3: さぽーとさっぽろ退職金 | Y3: 解約時積立 | Z3: 解約時 | AA3: さぽーとさっぽろ退職金 | AB3: さぽーとさっぽろ解約時 | AC3: ２９年度末 累計積立 見合額 | AD3: ２９年度末 | AE3: ２９年度末 | AF3: ２９年度末迄 | AG3: 定年到達 | AH3: 定年時 | AI3: 定年時 | AJ3: 定年時 | AK3: 定年時 | AL3: 備 考 | AO3: 累計積立 見合額 （Ａ） | AP3: 支払想定額 （Ｂ） | AQ3: （Ａ）-（Ｂ） 差額
C4: 積立額 | D4: 加入年月日 | E4: 通算見合額 | F4: 既支払額 | G4: 解約年月日 | H4: 通算積立期間 | J4: 支払想定額 | K4: 支給率 | L4: 通算積立期間 | M4: 年月日 | N4: 通算積立期間 | O4: 通算積立額 | P4: 支給率 | Q4: 支払退職金 | W4: 積立額 | X4: 加入年月日 | Y4: 通算見合額 | Z4: 既支払額 | AA4: 解約年月日 | AB4: 通算積立期間 | AD4: 支払想定額 | AE4: 支給率 | AF4: 通算積立期間 | AG4: 年月日 | AH4: 通算積立期間 | AI4: 通算積立額 | AJ4: 支給率 | AK4: 支払退職金
A5: 市場 | B5: 41061 | C5: 1400 | D5: 41091 | E5: 25200 | F5: 24070 | G5: 41639 | H5: 1年6ヶ月 | I5: 79800 | J5: =I5*K5 -> 78738.66 | K5: 0.9867 | L5: =DATEDIF(B5,$L$2,"y")&"年"&DATEDIF(B5,$L$2,"ym")&"ヶ月" -> 4年9ヶ月 | Q5: =O5*P5-F5 -> -24070 | R5: 燃料部 | U5: 市場 | V5: 41061 | W5: 1400 | X5: 41091 | Y5: 25200 | Z5: 24070 | AA5: 41639 | AB5: 1年6ヶ月 | AC5: 106600 | AD5: =AC5*AE5 -> 106269.54 | AE5: 0.9969 | AF5: =DATEDIF(V5,$L$2,"y")&"年"&DATEDIF(V5,$L$2,"ym")&"ヶ月" -> 4年9ヶ月 | AJ5: 1.0064 | AK5: =AI5*AJ5-Z5 -> -24070 | AL5: 燃料部 | AO5: =AC5-I5 -> 26800 | AP5: =AD5-J5 -> 27530.88 | AQ5: =AP5-AO5 -> 730.88
A6: 吉 | B6: 41760 | C6: 1400 | D6: - | E6: - | F6: - | G6: - | H6: - | I6: 47600 | J6: =I6*K6 -> 46467.12 | K6: 0.9762 | L6: =DATEDIF(B6,$L$2,"y")&"年"&DATEDIF(B6,$L$2,"ym")&"ヶ月" -> 2年10ヶ月 | Q6: =O6*P6-F6 -> #VALUE! | R6: 倶知安福光営業所 | U6: 吉 | V6: 41760 | W6: 1400 | X6: - | Y6: - | Z6: - | AA6: - | AB6: - | AC6: 64400 | AD6: =AC6*AE6 -> 63330.96 | AE6: 0.9834 | AF6: =DATEDIF(V6,$L$2,"y")&"年"&DATEDIF(V6,$L$2,"ym")&"ヶ月" -> 2年10ヶ月 | AK6: =AI6*AJ6-Z6 -> #VALUE! | AL6: 倶知安福光営業所 | AO6: =AC6-I6 -> 16800 | AP6: =AD6-J6 -> 16863.84 | AQ6: =AP6-AO6 -> 63.84
A7: 川村 | B7: 42095 | C7: 1400 | D7: - | E7: - | F7: - | G7: - | H7: - | I7: 19600 | J7: =I7*K7+180000 -> 198427.92 | K7: 0.9402 | L7: =DATEDIF(B7,$L$2,"y")&"年"&DATEDIF(B7,$L$2,"ym")&"ヶ月" -> 1年11ヶ月 | Q7: =O7*P7-F7 -> #VALUE! | R7: 小樽支店 | AR7: 28.6末自己都合退職
A8: 佐藤裕 | B8: 42125 | C8: 1400 | D8: - | E8: - | F8: - | G8: - | H8: - | I8: 30800 | J8: =I8*K8 -> 29589.56 | K8: 0.9607 | L8: =DATEDIF(B8,$L$2,"y")&"年"&DATEDIF(B8,$L$2,"ym")&"ヶ月" -> 1年10ヶ月 | Q8: =O8*P8-F8 -> #VALUE! | R8: 函館支店 | U8: 佐藤裕 | V8: 42125 | W8: 1400 | X8: - | Y8: - | Z8: - | AA8: - | AB8: - | AC8: 47600 | AD8: =AC8*AE8 -> 46467.12 | AE8: 0.9762 | AF8: =DATEDIF(V8,$L$2,"y")&"年"&DATEDIF(V8,$L$2,"ym")&"ヶ月" -> 1年10ヶ月 | AK8: =AI8*AJ8-Z8 -> #VALUE! | AL8: 函館支店 | AO8: =AC8-I8 -> 16800 | AP8: =AD8-J8 -> 16877.56 | AQ8: =AP8-AO8 -> 77.56
A9: 真坂 | B9: 42125 | C9: 1400 | D9: - | E9: - | F9: - | G9: - | H9: - | I9: 30800 | J9: =I9*K9 -> 29589.56 | K9: 0.9607 | L9: =DATEDIF(B9,$L$2,"y")&"年"&DATEDIF(B9,$L$2,"ym")&"ヶ月" -> 1年10ヶ月 | Q9: =O9*P9-F9 -> #VALUE! | R9: 燃料・資源 | U9: 真坂 | V9: 42125 | W9: 1400 | X9: - | Y9: - | Z9: - | AA9: - | AB9: - | AC9: 47600 | AD9: =AC9*AE9 -> 46467.12 | AE9: 0.9762 | AF9: =DATEDIF(V9,$L$2,"y")&"年"&DATEDIF(V9,$L$2,"ym")&"ヶ月" -> 1年10ヶ月 | AK9: =AI9*AJ9-Z9 -> #VALUE! | AL9: 燃料・資源 | AO9: =AC9-I9 -> 16800 | AP9: =AD9-J9 -> 16877.56 | AQ9: =AP9-AO9 -> 77.56
AQ10: =AP10-AO10 -> 0
A11: 俵 | B11: 40664 | C11: 1400 | D11: 40695 | E11: 43400 | F11: 42350 | G11: 41639 | H11: 2年7ヶ月 | I11: 94600 | J11: =I11*K11 -> 93814.82 | K11: 0.9917 | L11: 5年4ヶ月 | M11: 42626 | N11: 5年4ヶ月 | O11: 94600 | P11: 0.9917 | Q11: =O11*P11-F11 -> 51464.82 | R11: 倉庫部札幌倉庫課 | AR11: 28.9定年到達
AQ12: =AP12-AO12 -> 0
A13: 六渡 | B13: 39173 | C13: 3400 | D13: 39539 | E13: 123800 | F13: 122990 | G13: 41729 | H13: 6年0ヶ月 | I13: 250600 | J13: =I13*K13 -> 251401.92 | K13: 1.0032 | L13: =DATEDIF(B13,$L$2,"y")&"年"&DATEDIF(B13,$L$2,"ym")&"ヶ月" -> 9年11ヶ月 | Q13: =O13*P13-F13 -> -122990 | R13: 資源部福井砕石所 | U13: 六渡 | V13: 39173 | W13: 3400 | X13: 39539 | Y13: 123800 | Z13: 122990 | AA13: 41729 | AB13: 6年0ヶ月 | AC13: 290200 | AD13: =AC13*AE13 -> 291825.12 | AE13: 1.0056 | AF13: =DATEDIF(V13,$M$11,"y")&"年"&DATEDIF(V13,$M$11,"ym")&"ヶ月" -> 9年5ヶ月 | AG13: 43097 | AJ13: 1.0056 | AK13: =AI13*AJ13-Z13 -> -122990 | AL13: 福井砕石所 | AO13: =AC13-I13 -> 39600 | AP13: =AD13-J13 -> 40423.2 | AQ13: =AP13-AO13 -> 823.2
A14: 高森 | B14: 38108 | C14: 4400 | D14: 38139 | E14: 247200 | F14: 249190 | G14: 41729 | H14: 9年10ヶ月 | I14: 395800 | J14: =I14*K14 -> 400549.6 | K14: 1.012 | L14: 12年8ヶ月 | M14: 42765 | N14: 12年8ヶ月 | O14: 395800 | P14: 1.012 | Q14: =O14*P14-F14 -> 151359.6 | R14: 資源部福井砕石所 | AR14: 29.1定年到達
A15: 坂口 | B15: 38473 | C15: 4400 | D15: 38504 | E15: 206400 | F15: 207300 | G15: 41729 | H15: 8年10ヶ月 | I15: 351800 | J15: =I15*K15 -> 355106.92 | K15: 1.0094 | L15: =DATEDIF(B15,$L$2,"y")&"年"&DATEDIF(B15,$L$2,"ym")&"ヶ月" -> 11年10ヶ月 | Q15: =O15*P15-F15 -> -207300 | R15: 資源部福井砕石所 | U15: 坂口 | V15: 38473 | W15: 4400 | X15: 38504 | Y15: 206400 | Z15: 207300 | AA15: 41729 | AB15: 8年10ヶ月 | AC15: 404600 | AD15: =AC15*AE15 -> 409697.96 | AE15: 1.0126 | AF15: =DATEDIF(V15,$L$2,"y")&"年"&DATEDIF(V15,$L$2,"ym")&"ヶ月" -> 11年10ヶ月 | AK15: =AI15*AJ15-Z15 -> -207300 | AL15: 福井砕石所 | AO15: =AC15-I15 -> 52800 | AP15: =AD15-J15 -> 54591.04 | AQ15: =AP15-AO15 -> 1791.04
A16: 三上 | B16: 38473 | C16: 4400 | D16: 38504 | E16: 206400 | F16: 207300 | G16: 41729 | H16: 8年10ヶ月 | I16: 351800 | J16: =I16*K16 -> 355106.92 | K16: 1.0094 | L16: =DATEDIF(B16,$L$2,"y")&"年"&DATEDIF(B16,$L$2,"ym")&"ヶ月" -> 11年10ヶ月 | Q16: =O16*P16-F16 -> -207300 | R16: 資源部福井砕石所 | U16: 三上 | V16: 38473 | W16: 4400 | X16: 38504 | Y16: 206400 | Z16: 207300 | AA16: 41729 | AB16: 8年10ヶ月 | AC16: 404600 | AD16: =AC16*AE16 -> 409697.96 | AE16: 1.0126 | AF16: =DATEDIF(V16,$L$2,"y")&"年"&DATEDIF(V16,$L$2,"ym")&"ヶ月" -> 11年10ヶ月 | AK16: =AI16*AJ16-Z16 -> -207300 | AL16: 福井砕石所 | AO16: =AC16-I16 -> 52800 | AP16: =AD16-J16 -> 54591.04 | AQ16: =AP16-AO16 -> 1791.04
A17: 奥井 | B17: 41030 | C17: 1400 | D17: 41061 | E17: 30800 | F17: 29680 | G17: 41729 | H17: 1年10ヶ月 | I17: 81200 | J17: =I17*K17 -> 80144.4 | K17: 0.987 | L17: =DATEDIF(B17,$L$2,"y")&"年"&DATEDIF(B17,$L$2,"ym")&"ヶ月" -> 4年10ヶ月 | Q17: =O17*P17-F17 -> -29680 | R17: 資源部福井砕石所 | U17: 奥井 | V17: 41030 | W17: 1400 | X17: 41061 | Y17: 30800 | Z17: 29680 | AA17: 41729 | AB17: 1年10ヶ月 | AC17: 109000 | AD17: =AC17*AE17 -> 108771.1 | AE17: 0.9979 | AF17: =DATEDIF(V17,$L$2,"y")&"年"&DATEDIF(V17,$L$2,"ym")&"ヶ月" -> 4年10ヶ月 | AJ17: 1.0062 | AK17: =AI17*AJ17-Z17 -> -29680 | AL17: 福井砕石所 | AO17: =AC17-I17 -> 27800 | AP17: =AD17-J17 -> 28626.7 | AQ17: =AP17-AO17 -> 826.7
A18: 竹井 | B18: 41030 | C18: 1400 | D18: 41061 | E18: 30800 | F18: 29680 | G18: 41729 | H18: 1年10ヶ月 | I18: 81200 | J18: =I18*K18 -> 80144.4 | K18: 0.987 | L18: =DATEDIF(B18,$L$2,"y")&"年"&DATEDIF(B18,$L$2,"ym")&"ヶ月" -> 4年10ヶ月 | Q18: =O18*P18-F18 -> -29680 | R18: 資源部福井砕石所 | U18: 竹井 | V18: 41030 | W18: 1400 | X18: 41061 | Y18: 30800 | Z18: 29680 | AA18: 41729 | AB18: 1年10ヶ月 | AC18: 109000 | AD18: =AC18*AE18 -> 108771.1 | AE18: 0.9979 | AF18: =DATEDIF(V18,$L$2,"y")&"年"&DATEDIF(V18,$L$2,"ym")&"ヶ月" -> 4年10ヶ月 | AK18: =AI18*AJ18-Z18 -> -29680 | AL18: 福井砕石所 | AO18: =AC18-I18 -> 27800 | AP18: =AD18-J18 -> 28626.7 | AQ18: =AP18-AO18 -> 826.7
A19: 佐々木和 | B19: 41944 | C19: 1400 | D19: - | E19: - | F19: - | G19: - | H19: - | I19: 39200 | J19: =I19*K19 -> 38024 | K19: 0.97 | L19: =DATEDIF(B19,$L$2,"y")&"年"&DATEDIF(B19,$L$2,"ym")&"ヶ月" -> 2年4ヶ月 | Q19: =O19*P19-F19 -> #VALUE! | R19: 資源部福井砕石所 | U19: 佐々木和 | V19: 41944 | W19: 1400 | X19: - | Y19: - | Z19: - | AA19: - | AB19: - | AC19: 56000 | AD19: =AC19*AE19 -> 54896.8 | AE19: 0.9803 | AF19: =DATEDIF(V19,$L$2,"y")&"年"&DATEDIF(V19,$L$2,"ym")&"ヶ月" -> 2年4ヶ月 | AK19: =AI19*AJ19-Z19 -> #VALUE! | AL19: 福井砕石所 | AO19: =AC19-I19 -> 16800 | AP19: =AD19-J19 -> 16872.8 | AQ19: =AP19-AO19 -> 72.8
A20: 堀井 | B20: 42186 | C20: 1400 | D20: - | E20: - | F20: - | G20: - | H20: - | I20: 19600 | J20: =I20*K20 -> 18427.92 | K20: 0.9402 | L20: =DATEDIF(B20,$L$2,"y")&"年"&DATEDIF(B20,$L$2,"ym")&"ヶ月" -> 1年8ヶ月 | Q20: =O20*P20-F20 -> #VALUE! | R20: 資源部福井砕石所 | AR20: 28.8末自己都合退職
A21: 澤口 | B21: 42278 | D21: - | E21: - | F21: - | G21: - | H21: - | I21: 23800 | J21: =I21*K21 -> 22560.02 | K21: 0.9479 | L21: =DATEDIF(B21,$L$2,"y")&"年"&DATEDIF(B21,$L$2,"ym")&"ヶ月" -> 1年5ヶ月 | Q21: =O21*P21-F21 -> #VALUE! | R21: 資源部福井砕石所 | U21: 澤口 | V21: 42278 | X21: - | Y21: - | Z21: - | AA21: - | AB21: - | AC21: 40600 | AD21: =AC21*AE21 -> 39422.6 | AE21: 0.971 | AF21: =DATEDIF(V21,$L$2,"y")&"年"&DATEDIF(V21,$L$2,"ym")&"ヶ月" -> 1年5ヶ月 | AK21: =AI21*AJ21-Z21 -> #VALUE! | AL21: 福井砕石所 | AO21: =AC21-I21 -> 16800 | AP21: =AD21-J21 -> 16862.58 | AQ21: =AP21-AO21 -> 62.58
A22: 蠟山 | B22: 42491 | D22: - | E22: - | F22: - | G22: - | H22: - | I22: 14000 | J22: =I22*K22 -> 10910.2 | K22: 0.7793 | L22: =DATEDIF(B22,$L$2,"y")&"年"&DATEDIF(B22,$L$2,"ym")&"ヶ月" -> 0年10ヶ月 | R22: 倉庫部釧路倉庫課 | U22: 蠟山 | V22: 42491 | X22: - | Y22: - | Z22: - | AA22: - | AB22: - | AC22: 30800 | AD22: =AC22*AE22 -> 29589.56 | AE22: 0.9607 | AF22: =DATEDIF(V22,$L$2,"y")&"年"&DATEDIF(V22,$L$2,"ym")&"ヶ月" -> 0年10ヶ月 | AL22: 倉庫部釧路倉庫課 | AO22: =AC22-I22 -> 16800 | AP22: =AD22-J22 -> 18679.36 | AQ22: =AP22-AO22 -> 1879.36
A23: 赤枝 | B23: 42522 | D23: - | E23: - | F23: - | G23: - | H23: - | I23: 2800 | J23: 2800 | K23: - | L23: =DATEDIF(B23,$L$2,"y")&"年"&DATEDIF(B23,$L$2,"ym")&"ヶ月" -> 0年9ヶ月 | R23: 倉庫部札幌倉庫課 | AR23: 28.9末試用期間満了退職
A24: 引田 | B24: 42522 | D24: - | E24: - | F24: - | G24: - | H24: - | I24: 12600 | J24: =I24*K24 -> 8836.38 | K24: 0.7013 | L24: =DATEDIF(B24,$L$2,"y")&"年"&DATEDIF(B24,$L$2,"ym")&"ヶ月" -> 0年9ヶ月 | R24: 資源部美唄炭砿 | U24: 引田 | V24: 42522 | X24: - | Y24: - | Z24: - | AA24: - | AB24: - | AC24: 29400 | AD24: =AC24*AE24 -> 28168.14 | AE24: 0.9581 | AF24: =DATEDIF(V24,$L$2,"y")&"年"&DATEDIF(V24,$L$2,"ym")&"ヶ月" -> 0年9ヶ月 | AL24: 資源部美唄炭砿 | AO24: =AC24-I24 -> 16800 | AP24: =AD24-J24 -> 19331.76 | AQ24: =AP24-AO24 -> 2531.76
A25: 古村 | B25: 42552 | D25: - | E25: - | F25: - | G25: - | H25: - | I25: 11200 | J25: =I25*K25 -> 6982.08 | K25: 0.6234 | L25: =DATEDIF(B25,$L$2,"y")&"年"&DATEDIF(B25,$L$2,"ym")&"ヶ月" -> 0年8ヶ月 | R25: 倉庫部石狩倉庫課 | U25: 古村 | V25: 42552 | X25: - | Y25: - | Z25: - | AA25: - | AB25: - | AC25: 28000 | AD25: =AC25*AE25 -> 26756.8 | AE25: 0.9556 | AF25: =DATEDIF(V25,$L$2,"y")&"年"&DATEDIF(V25,$L$2,"ym")&"ヶ月" -> 0年8ヶ月 | AL25: 倉庫部石狩倉庫課 | AO25: =AC25-I25 -> 16800 | AP25: =AD25-J25 -> 19774.72 | AQ25: =AP25-AO25 -> 2974.72
A26: 佐々木幸 | B26: 42552 | D26: - | E26: - | F26: - | G26: - | H26: - | I26: 11200 | J26: =I26*K26 -> 6982.08 | K26: 0.6234 | L26: =DATEDIF(B26,$L$2,"y")&"年"&DATEDIF(B26,$L$2,"ym")&"ヶ月" -> 0年8ヶ月 | R26: 資源部美唄炭砿 | U26: 佐々木幸 | V26: 42552 | X26: - | Y26: - | Z26: - | AA26: - | AB26: - | AC26: 28000 | AD26: =AC26*AE26 -> 26756.8 | AE26: 0.9556 | AF26: =DATEDIF(V26,$L$2,"y")&"年"&DATEDIF(V26,$L$2,"ym")&"ヶ月" -> 0年8ヶ月 | AL26: 資源部美唄炭砿 | AO26: =AC26-I26 -> 16800 | AP26: =AD26-J26 -> 19774.72 | AQ26: =AP26-AO26 -> 2974.72
A27: 田中隆 | B27: 42675 | D27: - | E27: - | F27: - | G27: - | H27: - | I27: 5600 | J27: =I27*K27 -> 1745.52 | K27: 0.3117 | L27: =DATEDIF(B27,$L$2,"y")&"年"&DATEDIF(B27,$L$2,"ym")&"ヶ月" -> 0年4ヶ月 | R27: 資源部管理課 | U27: 田中隆 | V27: 42675 | X27: - | Y27: - | Z27: - | AA27: - | AB27: - | AC27: 22400 | AD27: =AC27*AE27 -> 21174.72 | AE27: 0.9453 | AF27: =DATEDIF(V27,$L$2,"y")&"年"&DATEDIF(V27,$L$2,"ym")&"ヶ月" -> 0年4ヶ月 | AL27: 資源部管理課 | AO27: =AC27-I27 -> 16800 | AP27: =AD27-J27 -> 19429.2 | AQ27: =AP27-AO27 -> 2629.2
A28: 佐藤路 | B28: 42675 | D28: - | E28: - | F28: - | G28: - | H28: - | I28: 5600 | J28: =I28*K28 -> 1745.52 | K28: 0.3117 | L28: =DATEDIF(B28,$L$2,"y")&"年"&DATEDIF(B28,$L$2,"ym")&"ヶ月" -> 0年4ヶ月 | R28: 倉庫部釧路倉庫課 | U28: 佐藤路 | V28: 42675 | X28: - | Y28: - | Z28: - | AA28: - | AB28: - | AC28: 22400 | AD28: =AC28*AE28 -> 21174.72 | AE28: 0.9453 | AF28: =DATEDIF(V28,$L$2,"y")&"年"&DATEDIF(V28,$L$2,"ym")&"ヶ月" -> 0年4ヶ月 | AL28: 倉庫部釧路倉庫課 | AO28: =AC28-I28 -> 16800 | AP28: =AD28-J28 -> 19429.2 | AQ28: =AP28-AO28 -> 2629.2
A29: 玉田 | B29: 42705 | D29: - | E29: - | F29: - | G29: - | H29: - | I29: 4200 | J29: =I29*K29 -> 981.96 | K29: 0.2338 | L29: =DATEDIF(B29,$L$2,"y")&"年"&DATEDIF(B29,$L$2,"ym")&"ヶ月" -> 0年3ヶ月 | R29: 倉庫部釧路倉庫課 | U29: 玉田 | V29: 42705 | X29: - | Y29: - | Z29: - | AA29: - | AB29: - | AC29: 21000 | AD29: =AC29*AE29 -> 19798.8 | AE29: 0.9428 | AF29: =DATEDIF(V29,$L$2,"y")&"年"&DATEDIF(V29,$L$2,"ym")&"ヶ月" -> 0年3ヶ月 | AL29: 倉庫部釧路倉庫課 | AO29: =AC29-I29 -> 16800 | AP29: =AD29-J29 -> 18816.84 | AQ29: =AP29-AO29 -> 2016.84
A30: 計22名 | F30: =SUM(F5:F29) -> 912560 | I30: =SUM(I5:I29) -> 1965400 | J30: =SUM(J5:J29) -> 2119077.5 | U30: 計18名 | Z30: =SUM(Z5:Z29) -> 621020 | AC30: =SUM(AC5:AC29) -> 1862200 | AD30: =SUM(AD5:AD29) -> 1859036.9 | AO30: =SUM(AO5:AO29) -> 429200 | AP30: =SUM(AP5:AP29) -> 453979.7 | AQ30: =SUM(AQ5:AQ29) -> 24779.7
H31: 28年度伸び額 | I31: =I30-Ｈ27年度末退職金!I25 -> 395600 | J31: =J30-Ｈ27年度末退職金!J25 -> 573746.14 | AB31: 29年度伸び額 | AC31: =AC30-Ｈ28年度末退職金!AC34 -> 1862200 | AD31: =AD30-Ｈ28年度末退職金!AD34 -> 1859036.9
C32: =1400*12 -> 16800
C33: =1400*24 -> 33600 | J33: →自己都合等退職者 | AO33: 28年度途中の退職者及び定年到達者は対象外。
C34: =1400*36 -> 50400 | J34: →定年到達者 | AO34: 上記計算は29年度在籍者のみ対象。
C35: =1400*48 -> 67200
C36: =C35+(1400*11) -> 82600
C37: =C36+2400 -> 85000
C38: =C37+2400*12 -> 113800
C39: =C38+2400*12 -> 142600
C40: =C39+2400*11 -> 169000
...

Sheet 退職金推移0年～20年
D1: 準職員退職金推移表
B3: 勤続年数 | C3: 積立金額 | D3: 支給率 | E3: 支給額 | F3: 勤続年数 | G3: 積立金額 | H3: 支給率 | I3: 支給額 | J3: 勤続年数 | K3: 積立金額 | L3: 支給率 | M3: 支給額 | N3: 勤続年数 | O3: 積立金額 | P3: 支給率 | Q3: 支給額
B4: 入社月 | C4: 0 | D4: 0 | E4: =C4*D4 -> 0 | F4: 5年0ヶ月 | G4: =C63+2400 -> 85000 | H4: 0.9875 | I4: =G4*H4 -> 83937.5 | J4: 10年0ヶ月 | K4: =G63+4400 -> 255000 | L4: 1.0034 | M4: =K4*L4 -> 255867 | N4: 15年0ヶ月 | O4: =K63+4400 -> 519000 | P4: 1.0196 | Q4: =O4*P4 -> 529172.4
B5: 1ヶ月 | C5: 1400 | D5: =0+(D16-D4)*1/12 -> 0.077925 | E5: =C5*D5 -> 109.095 | F5: 5年1ヶ月 | G5: =G4+2400 -> 87400 | H5: =H4+(H16-H4)*1/12 -> 0.98854167 | I5: =G5*H5 -> 86398.542 | J5: 10年1ヶ月 | K5: =K4+4400 -> 259400 | L5: =L4+(L16-L4)*1/12 -> 1.003675 | M5: =K5*L5 -> 260353.3 | N5: 15年1ヶ月 | O5: =O4+4400 -> 523400 | P5: =P4+(P16-P4)*1/12 -> 1.019875 | Q5: =O5*P5 -> 533802.58
B6: 2ヶ月 | C6: =C5+1400 -> 2800 | D6: =0+(D16-D4)*2/12 -> 0.15585 | E6: =C6*D6 -> 436.38 | F6: 5年2ヶ月 | G6: =G5+2400 -> 89800 | H6: =H4+(H16-H4)*2/12 -> 0.98958333 | I6: =G6*H6 -> 88864.583 | J6: 10年2ヶ月 | K6: =K5+4400 -> 263800 | L6: =L4+(L16-L4)*2/12 -> 1.00395 | M6: =K6*L6 -> 264842.01 | N6: 15年2ヶ月 | O6: =O5+4400 -> 527800 | P6: =P4+(P16-P4)*2/12 -> 1.02015 | Q6: =O6*P6 -> 538435.17
B7: 3ヶ月 | C7: =C6+1400 -> 4200 | D7: =0+(D16-D4)*3/12 -> 0.233775 | E7: =C7*D7 -> 981.855 | F7: 5年3ヶ月 | G7: =G6+2400 -> 92200 | H7: =H4+(H16-H4)*3/12 -> 0.990625 | I7: =G7*H7 -> 91335.625 | J7: 10年3ヶ月 | K7: =K6+4400 -> 268200 | L7: =L4+(L16-L4)*3/12 -> 1.004225 | M7: =K7*L7 -> 269333.14 | N7: 15年3ヶ月 | O7: =O6+4400 -> 532200 | P7: =P4+(P16-P4)*3/12 -> 1.020425 | Q7: =O7*P7 -> 543070.18
B8: 4ヶ月 | C8: =C7+1400 -> 5600 | D8: =0+(D16-D4)*4/12 -> 0.3117 | E8: =C8*D8 -> 1745.52 | F8: 5年4ヶ月 | G8: =G7+2400 -> 94600 | H8: =H4+(H16-H4)*4/12 -> 0.99166667 | I8: =G8*H8 -> 93811.667 | J8: 10年4ヶ月 | K8: =K7+4400 -> 272600 | L8: =L4+(L16-L4)*4/12 -> 1.0045 | M8: =K8*L8 -> 273826.7 | N8: 15年4ヶ月 | O8: =O7+4400 -> 536600 | P8: =P4+(P16-P4)*4/12 -> 1.0207 | Q8: =O8*P8 -> 547707.62
B9: 5ヶ月 | C9: =C8+1400 -> 7000 | D9: =0+(D16-D4)*5/12 -> 0.389625 | E9: =C9*D9 -> 2727.375 | F9: 5年5ヶ月 | G9: =G8+2400 -> 97000 | H9: =H4+(H16-H4)*5/12 -> 0.99270833 | I9: =G9*H9 -> 96292.708 | J9: 10年5ヶ月 | K9: =K8+4400 -> 277000 | L9: =L4+(L16-L4)*5/12 -> 1.004775 | M9: =K9*L9 -> 278322.67 | N9: 15年5ヶ月 | O9: =O8+4400 -> 541000 | P9: =P4+(P16-P4)*5/12 -> 1.020975 | Q9: =O9*P9 -> 552347.47
B10: 6ヶ月 | C10: =C9+1400 -> 8400 | D10: =0+(D16-D4)*6/12 -> 0.46755 | E10: =C10*D10 -> 3927.42 | F10: 5年6ヶ月 | G10: =G9+2400 -> 99400 | H10: =H4+(H16-H4)*6/12 -> 0.99375 | I10: =G10*H10 -> 98778.75 | J10: 10年6ヶ月 | K10: =K9+4400 -> 281400 | L10: =L4+(L16-L4)*6/12 -> 1.00505 | M10: =K10*L10 -> 282821.07 | N10: 15年6ヶ月 | O10: =O9+4400 -> 545400 | P10: =P4+(P16-P4)*6/12 -> 1.02125 | Q10: =O10*P10 -> 556989.75
B11: 7ヶ月 | C11: =C10+1400 -> 9800 | D11: =0+(D16-D4)*7/12 -> 0.545475 | E11: =C11*D11 -> 5345.655 | F11: 5年7ヶ月 | G11: =G10+2400 -> 101800 | H11: =H4+(H16-H4)*7/12 -> 0.99479167 | I11: =G11*H11 -> 101269.79 | J11: 10年7ヶ月 | K11: =K10+4400 -> 285800 | L11: =L4+(L16-L4)*7/12 -> 1.005325 | M11: =K11*L11 -> 287321.89 | N11: 15年7ヶ月 | O11: =O10+4400 -> 549800 | P11: =P4+(P16-P4)*7/12 -> 1.021525 | Q11: =O11*P11 -> 561634.45
B12: 8ヶ月 | C12: =C11+1400 -> 11200 | D12: =0+(D16-D4)*8/12 -> 0.6234 | E12: =C12*D12 -> 6982.08 | F12: 5年8ヶ月 | G12: =G11+2400 -> 104200 | H12: =H4+(H16-H4)*8/12 -> 0.99583333 | I12: =G12*H12 -> 103765.83 | J12: 10年8ヶ月 | K12: =K11+4400 -> 290200 | L12: =L4+(L16-L4)*8/12 -> 1.0056 | M12: =K12*L12 -> 291825.12 | N12: 15年8ヶ月 | O12: =O11+4400 -> 554200 | P12: =P4+(P16-P4)*8/12 -> 1.0218 | Q12: =O12*P12 -> 566281.56
B13: 9ヶ月 | C13: =C12+1400 -> 12600 | D13: =0+(D16-D4)*9/12 -> 0.701325 | E13: =C13*D13 -> 8836.695 | F13: 5年9ヶ月 | G13: =G12+2400 -> 106600 | H13: =H4+(H16-H4)*9/12 -> 0.996875 | I13: =G13*H13 -> 106266.88 | J13: 10年9ヶ月 | K13: =K12+4400 -> 294600 | L13: =L4+(L16-L4)*9/12 -> 1.005875 | M13: =K13*L13 -> 296330.78 | N13: 15年9ヶ月 | O13: =O12+4400 -> 558600 | P13: =P4+(P16-P4)*9/12 -> 1.022075 | Q13: =O13*P13 -> 570931.1
B14: 10ヶ月 | C14: =C13+1400 -> 14000 | D14: =0+(D16-D4)*10/12 -> 0.77925 | E14: =C14*D14 -> 10909.5 | F14: 5年10ヶ月 | G14: =G13+2400 -> 109000 | H14: =H4+(H16-H4)*10/12 -> 0.99791667 | I14: =G14*H14 -> 108772.92 | J14: 10年10ヶ月 | K14: =K13+4400 -> 299000 | L14: =L4+(L16-L4)*10/12 -> 1.00615 | M14: =K14*L14 -> 300838.85 | N14: 15年10ヶ月 | O14: =O13+4400 -> 563000 | P14: =P4+(P16-P4)*10/12 -> 1.02235 | Q14: =O14*P14 -> 575583.05
B15: 11ヶ月 | C15: =C14+1400 -> 15400 | D15: =0+(D16-D4)*11/12 -> 0.857175 | E15: =C15*D15 -> 13200.495 | F15: 5年11ヶ月 | G15: =G14+2400 -> 111400 | H15: =H4+(H16-H4)*11/12 -> 0.99895833 | I15: =G15*H15 -> 111283.96 | J15: 10年11ヶ月 | K15: =K14+4400 -> 303400 | L15: =L4+(L16-L4)*11/12 -> 1.006425 | M15: =K15*L15 -> 305349.34 | N15: 15年11ヶ月 | O15: =O14+4400 -> 567400 | P15: =P4+(P16-P4)*11/12 -> 1.022625 | Q15: =O15*P15 -> 580237.42
B16: 1年0ヶ月 | C16: =C15+1400 -> 16800 | D16: 0.9351 | E16: =C16*D16 -> 15709.68 | F16: 6年0ヶ月 | G16: =G15+2400 -> 113800 | H16: 1 | I16: =G16*H16 -> 113800 | J16: 11年0ヶ月 | K16: =K15+4400 -> 307800 | L16: 1.0067 | M16: =K16*L16 -> 309862.26 | N16: 16年0ヶ月 | O16: =O15+4400 -> 571800 | P16: 1.0229 | Q16: =O16*P16 -> 584894.22
B17: 1年1ヶ月 | C17: =C16+1400 -> 18200 | D17: =D16+(D28-D16)*1/12 -> 0.93765833 | E17: =C17*D17 -> 17065.382 | F17: 6年1ヶ月 | G17: =G16+2400 -> 116200 | H17: =H16+(H28-H16)*1/12 -> 1.0000333 | I17: =G17*H17 -> 116203.87 | J17: 11年1ヶ月 | K17: =K16+4400 -> 312200 | L17: =L16+(L28-L16)*1/12 -> 1.0069667 | M17: =K17*L17 -> 314374.99 | N17: 16年1ヶ月 | O17: =O16+4400 -> 576200 | P17: =P16+(P28-P16)*1/12 -> 1.023175 | Q17: =O17*P17 -> 589553.43
B18: 1年2ヶ月 | C18: =C17+1400 -> 19600 | D18: =D16+(D28-D16)*2/12 -> 0.94021667 | E18: =C18*D18 -> 18428.247 | F18: 6年2ヶ月 | G18: =G17+2400 -> 118600 | H18: =H16+(H28-H16)*2/12 -> 1.0000667 | I18: =G18*H18 -> 118607.91 | J18: 11年2ヶ月 | K18: =K17+4400 -> 316600 | L18: =L16+(L28-L16)*2/12 -> 1.0072333 | M18: =K18*L18 -> 318890.07 | N18: 16年2ヶ月 | O18: =O17+4400 -> 580600 | P18: =P16+(P28-P16)*2/12 -> 1.02345 | Q18: =O18*P18 -> 594215.07
B19: 1年3ヶ月 | C19: =C18+1400 -> 21000 | D19: =D16+(D28-D16)*3/12 -> 0.942775 | E19: =C19*D19 -> 19798.275 | F19: 6年3ヶ月 | G19: =G18+2400 -> 121000 | H19: =H16+(H28-H16)*3/12 -> 1.0001 | I19: =G19*H19 -> 121012.1 | J19: 11年3ヶ月 | K19: =K18+4400 -> 321000 | L19: =L16+(L28-L16)*3/12 -> 1.0075 | M19: =K19*L19 -> 323407.5 | N19: 16年3ヶ月 | O19: =O18+4400 -> 585000 | P19: =P16+(P28-P16)*3/12 -> 1.023725 | Q19: =O19*P19 -> 598879.12
B20: 1年4ヶ月 | C20: =C19+1400 -> 22400 | D20: =D16+(D28-D16)*4/12 -> 0.94533333 | E20: =C20*D20 -> 21175.467 | F20: 6年4ヶ月 | G20: =G19+2400 -> 123400 | H20: =H16+(H28-H16)*4/12 -> 1.0001333 | I20: =G20*H20 -> 123416.45 | J20: 11年4ヶ月 | K20: =K19+4400 -> 325400 | L20: =L16+(L28-L16)*4/12 -> 1.0077667 | M20: =K20*L20 -> 327927.27 | N20: 16年4ヶ月 | O20: =O19+4400 -> 589400 | P20: =P16+(P28-P16)*4/12 -> 1.024 | Q20: =O20*P20 -> 603545.6
B21: 1年5ヶ月 | C21: =C20+1400 -> 23800 | D21: =D16+(D28-D16)*5/12 -> 0.94789167 | E21: =C21*D21 -> 22559.822 | F21: 6年5ヶ月 | G21: =G20+2400 -> 125800 | H21: =H16+(H28-H16)*5/12 -> 1.0001667 | I21: =G21*H21 -> 125820.97 | J21: 11年5ヶ月 | K21: =K20+4400 -> 329800 | L21: =L16+(L28-L16)*5/12 -> 1.0080333 | M21: =K21*L21 -> 332449.39 | N21: 16年5ヶ月 | O21: =O20+4400 -> 593800 | P21: =P16+(P28-P16)*5/12 -> 1.024275 | Q21: =O21*P21 -> 608214.49
B22: 1年6ヶ月 | C22: =C21+1400 -> 25200 | D22: =D16+(D28-D16)*6/12 -> 0.95045 | E22: =C22*D22 -> 23951.34 | F22: 6年6ヶ月 | G22: =G21+2400 -> 128200 | H22: =H16+(H28-H16)*6/12 -> 1.0002 | I22: =G22*H22 -> 128225.64 | J22: 11年6ヶ月 | K22: =K21+4400 -> 334200 | L22: =L16+(L28-L16)*6/12 -> 1.0083 | M22: =K22*L22 -> 336973.86 | N22: 16年6ヶ月 | O22: =O21+4400 -> 598200 | P22: =P16+(P28-P16)*6/12 -> 1.02455 | Q22: =O22*P22 -> 612885.81
B23: 1年7ヶ月 | C23: =C22+1400 -> 26600 | D23: =D16+(D28-D16)*7/12 -> 0.95300833 | E23: =C23*D23 -> 25350.022 | F23: 6年7ヶ月 | G23: =G22+2400 -> 130600 | H23: =H16+(H28-H16)*7/12 -> 1.0002333 | I23: =G23*H23 -> 130630.47 | J23: 11年7ヶ月 | K23: =K22+4400 -> 338600 | L23: =L16+(L28-L16)*7/12 -> 1.0085667 | M23: =K23*L23 -> 341500.67 | N23: 16年7ヶ月 | O23: =O22+4400 -> 602600 | P23: =P16+(P28-P16)*7/12 -> 1.024825 | Q23: =O23*P23 -> 617559.54
B24: 1年8ヶ月 | C24: =C23+1400 -> 28000 | D24: =D16+(D28-D16)*8/12 -> 0.95556667 | E24: =C24*D24 -> 26755.867 | F24: 6年8ヶ月 | G24: =G23+2400 -> 133000 | H24: =H16+(H28-H16)*8/12 -> 1.0002667 | I24: =G24*H24 -> 133035.47 | J24: 11年8ヶ月 | K24: =K23+4400 -> 343000 | L24: =L16+(L28-L16)*8/12 -> 1.0088333 | M24: =K24*L24 -> 346029.83 | N24: 16年8ヶ月 | O24: =O23+4400 -> 607000 | P24: =P16+(P28-P16)*8/12 -> 1.0251 | Q24: =O24*P24 -> 622235.7
B25: 1年9ヶ月 | C25: =C24+1400 -> 29400 | D25: =D16+(D28-D16)*9/12 -> 0.958125 | E25: =C25*D25 -> 28168.875 | F25: 6年9ヶ月 | G25: =G24+2400 -> 135400 | H25: =H16+(H28-H16)*9/12 -> 1.0003 | I25: =G25*H25 -> 135440.62 | J25: 11年9ヶ月 | K25: =K24+4400 -> 347400 | L25: =L16+(L28-L16)*9/12 -> 1.0091 | M25: =K25*L25 -> 350561.34 | N25: 16年9ヶ月 | O25: =O24+4400 -> 611400 | P25: =P16+(P28-P16)*9/12 -> 1.025375 | Q25: =O25*P25 -> 626914.27
B26: 1年10ヶ月 | C26: =C25+1400 -> 30800 | D26: =D16+(D28-D16)*10/12 -> 0.96068333 | E26: =C26*D26 -> 29589.047 | F26: 6年10ヶ月 | G26: =G25+2400 -> 137800 | H26: =H16+(H28-H16)*10/12 -> 1.0003333 | I26: =G26*H26 -> 137845.93 | J26: 11年10ヶ月 | K26: =K25+4400 -> 351800 | L26: =L16+(L28-L16)*10/12 -> 1.0093667 | M26: =K26*L26 -> 355095.19 | N26: 16年10ヶ月 | O26: =O25+4400 -> 615800 | P26: =P16+(P28-P16)*10/12 -> 1.02565 | Q26: =O26*P26 -> 631595.27
B27: 1年11ヶ月 | C27: =C26+1400 -> 32200 | D27: =D16+(D28-D16)*11/12 -> 0.96324167 | E27: =C27*D27 -> 31016.382 | F27: 6年11ヶ月 | G27: =G26+2400 -> 140200 | H27: =H16+(H28-H16)*11/12 -> 1.0003667 | I27: =G27*H27 -> 140251.41 | J27: 11年11ヶ月 | K27: =K26+4400 -> 356200 | L27: =L16+(L28-L16)*11/12 -> 1.0096333 | M27: =K27*L27 -> 359631.39 | N27: 16年11ヶ月 | O27: =O26+4400 -> 620200 | P27: =P16+(P28-P16)*11/12 -> 1.025925 | Q27: =O27*P27 -> 636278.68
B28: 2年0ヶ月 | C28: =C27+1400 -> 33600 | D28: 0.9658 | E28: =C28*D28 -> 32450.88 | F28: 7年0ヶ月 | G28: =G27+2400 -> 142600 | H28: 1.0004 | I28: =G28*H28 -> 142657.04 | J28: 12年0ヶ月 | K28: =K27+4400 -> 360600 | L28: 1.0099 | M28: =K28*L28 -> 364169.94 | N28: 17年0ヶ月 | O28: =O27+4400 -> 624600 | P28: 1.0262 | Q28: =O28*P28 -> 640964.52
B29: 2年1ヶ月 | C29: =C28+1400 -> 35000 | D29: =D28+(D40-D28)*1/12 -> 0.96684167 | E29: =C29*D29 -> 33839.458 | F29: 7年1ヶ月 | G29: =G28+2400 -> 145000 | H29: =H28+(H40-H28)*1/12 -> 1.0004167 | I29: =G29*H29 -> 145060.42 | J29: 12年1ヶ月 | K29: =K28+4400 -> 365000 | L29: =L28+(L40-L28)*1/12 -> 1.0101667 | M29: =K29*L29 -> 368710.83 | N29: 17年1ヶ月 | O29: =O28+4400 -> 629000 | P29: =P28+(P40-P28)*1/12 -> 1.026475 | Q29: =O29*P29 -> 645652.78
B30: 2年2ヶ月 | C30: =C29+1400 -> 36400 | D30: =D28+(D40-D28)*2/12 -> 0.96788333 | E30: =C30*D30 -> 35230.953 | F30: 7年2ヶ月 | G30: =G29+2400 -> 147400 | H30: =H28+(H40-H28)*2/12 -> 1.0004333 | I30: =G30*H30 -> 147463.87 | J30: 12年2ヶ月 | K30: =K29+4400 -> 369400 | L30: =L28+(L40-L28)*2/12 -> 1.0104333 | M30: =K30*L30 -> 373254.07 | N30: 17年2ヶ月 | O30: =O29+4400 -> 633400 | P30: =P28+(P40-P28)*2/12 -> 1.02675 | Q30: =O30*P30 -> 650343.45
B31: 2年3ヶ月 | C31: =C30+1400 -> 37800 | D31: =D28+(D40-D28)*3/12 -> 0.968925 | E31: =C31*D31 -> 36625.365 | F31: 7年3ヶ月 | G31: =G30+2400 -> 149800 | H31: =H28+(H40-H28)*3/12 -> 1.00045 | I31: =G31*H31 -> 149867.41 | J31: 12年3ヶ月 | K31: =K30+4400 -> 373800 | L31: =L28+(L40-L28)*3/12 -> 1.0107 | M31: =K31*L31 -> 377799.66 | N31: 17年3ヶ月 | O31: =O30+4400 -> 637800 | P31: =P28+(P40-P28)*3/12 -> 1.027025 | Q31: =O31*P31 -> 655036.55
B32: 2年4ヶ月 | C32: =C31+1400 -> 39200 | D32: =D28+(D40-D28)*4/12 -> 0.96996667 | E32: =C32*D32 -> 38022.693 | F32: 7年4ヶ月 | G32: =G31+2400 -> 152200 | H32: =H28+(H40-H28)*4/12 -> 1.0004667 | I32: =G32*H32 -> 152271.03 | J32: 12年4ヶ月 | K32: =K31+4400 -> 378200 | L32: =L28+(L40-L28)*4/12 -> 1.0109667 | M32: =K32*L32 -> 382347.59 | N32: 17年4ヶ月 | O32: =O31+4400 -> 642200 | P32: =P28+(P40-P28)*4/12 -> 1.0273 | Q32: =O32*P32 -> 659732.06
B33: 2年5ヶ月 | C33: =C32+1400 -> 40600 | D33: =D28+(D40-D28)*5/12 -> 0.97100833 | E33: =C33*D33 -> 39422.938 | F33: 7年5ヶ月 | G33: =G32+2400 -> 154600 | H33: =H28+(H40-H28)*5/12 -> 1.0004833 | I33: =G33*H33 -> 154674.72 | J33: 12年5ヶ月 | K33: =K32+4400 -> 382600 | L33: =L28+(L40-L28)*5/12 -> 1.0112333 | M33: =K33*L33 -> 386897.87 | N33: 17年5ヶ月 | O33: =O32+4400 -> 646600 | P33: =P28+(P40-P28)*5/12 -> 1.027575 | Q33: =O33*P33 -> 664430
B34: 2年6ヶ月 | C34: =C33+1400 -> 42000 | D34: =D28+(D40-D28)*6/12 -> 0.97205 | E34: =C34*D34 -> 40826.1 | F34: 7年6ヶ月 | G34: =G33+2400 -> 157000 | H34: =H28+(H40-H28)*6/12 -> 1.0005 | I34: =G34*H34 -> 157078.5 | J34: 12年6ヶ月 | K34: =K33+4400 -> 387000 | L34: =L28+(L40-L28)*6/12 -> 1.0115 | M34: =K34*L34 -> 391450.5 | N34: 17年6ヶ月 | O34: =O33+4400 -> 651000 | P34: =P28+(P40-P28)*6/12 -> 1.02785 | Q34: =O34*P34 -> 669130.35
B35: 2年7ヶ月 | C35: =C34+1400 -> 43400 | D35: =D28+(D40-D28)*7/12 -> 0.97309167 | E35: =C35*D35 -> 42232.178 | F35: 7年7ヶ月 | G35: =G34+2400 -> 159400 | H35: =H28+(H40-H28)*7/12 -> 1.0005167 | I35: =G35*H35 -> 159482.36 | J35: 12年7ヶ月 | K35: =K34+4400 -> 391400 | L35: =L28+(L40-L28)*7/12 -> 1.0117667 | M35: =K35*L35 -> 396005.47 | N35: 17年7ヶ月 | O35: =O34+4400 -> 655400 | P35: =P28+(P40-P28)*7/12 -> 1.028125 | Q35: =O35*P35 -> 673833.12
B36: 2年8ヶ月 | C36: =C35+1400 -> 44800 | D36: =D28+(D40-D28)*8/12 -> 0.97413333 | E36: =C36*D36 -> 43641.173 | F36: 7年8ヶ月 | G36: =G35+2400 -> 161800 | H36: =H28+(H40-H28)*8/12 -> 1.0005333 | I36: =G36*H36 -> 161886.29 | J36: 12年8ヶ月 | K36: =K35+4400 -> 395800 | L36: =L28+(L40-L28)*8/12 -> 1.0120333 | M36: =K36*L36 -> 400562.79 | N36: 17年8ヶ月 | O36: =O35+4400 -> 659800 | P36: =P28+(P40-P28)*8/12 -> 1.0284 | Q36: =O36*P36 -> 678538.32
B37: 2年9ヶ月 | C37: =C36+1400 -> 46200 | D37: =D28+(D40-D28)*9/12 -> 0.975175 | E37: =C37*D37 -> 45053.085 | F37: 7年9ヶ月 | G37: =G36+2400 -> 164200 | H37: =H28+(H40-H28)*9/12 -> 1.00055 | I37: =G37*H37 -> 164290.31 | J37: 12年9ヶ月 | K37: =K36+4400 -> 400200 | L37: =L28+(L40-L28)*9/12 -> 1.0123 | M37: =K37*L37 -> 405122.46 | N37: 17年9ヶ月 | O37: =O36+4400 -> 664200 | P37: =P28+(P40-P28)*9/12 -> 1.028675 | Q37: =O37*P37 -> 683245.94
B38: 2年10ヶ月 | C38: =C37+1400 -> 47600 | D38: =D28+(D40-D28)*10/12 -> 0.97621667 | E38: =C38*D38 -> 46467.913 | F38: 7年10ヶ月 | G38: =G37+2400 -> 166600 | H38: =H28+(H40-H28)*10/12 -> 1.0005667 | I38: =G38*H38 -> 166694.41 | J38: 12年10ヶ月 | K38: =K37+4400 -> 404600 | L38: =L28+(L40-L28)*10/12 -> 1.0125667 | M38: =K38*L38 -> 409684.47 | N38: 17年10ヶ月 | O38: =O37+4400 -> 668600 | P38: =P28+(P40-P28)*10/12 -> 1.02895 | Q38: =O38*P38 -> 687955.97
B39: 2年11ヶ月 | C39: =C38+1400 -> 49000 | D39: =D28+(D40-D28)*11/12 -> 0.97725833 | E39: =C39*D39 -> 47885.658 | F39: 7年11ヶ月 | G39: =G38+2400 -> 169000 | H39: =H28+(H40-H28)*11/12 -> 1.0005833 | I39: =G39*H39 -> 169098.58 | J39: 12年11ヶ月 | K39: =K38+4400 -> 409000 | L39: =L28+(L40-L28)*11/12 -> 1.0128333 | M39: =K39*L39 -> 414248.83 | N39: 17年11ヶ月 | O39: =O38+4400 -> 673000 | P39: =P28+(P40-P28)*11/12 -> 1.029225 | Q39: =O39*P39 -> 692668.43
B40: 3年0ヶ月 | C40: =C39+1400 -> 50400 | D40: 0.9783 | E40: =C40*D40 -> 49306.32 | F40: 8年0ヶ月 | G40: =G39+3400 -> 172400 | H40: 1.0006 | I40: =G40*H40 -> 172503.44 | J40: 13年0ヶ月 | K40: =K39+4400 -> 413400 | L40: 1.0131 | M40: =K40*L40 -> 418815.54 | N40: 18年0ヶ月 | O40: =O39+4400 -> 677400 | P40: 1.0295 | Q40: =O40*P40 -> 697383.3
B41: 3年1ヶ月 | C41: =C40+1400 -> 51800 | D41: =D40+(D52-D40)*1/12 -> 0.97880833 | E41: =C41*D41 -> 50702.272 | F41: 8年1ヶ月 | G41: =G40+3400 -> 175800 | H41: =H40+(H52-H40)*1/12 -> 1.0006167 | I41: =G41*H41 -> 175908.41 | J41: 13年1ヶ月 | K41: =K40+4400 -> 417800 | L41: =L40+(L52-L40)*1/12 -> 1.013375 | M41: =K41*L41 -> 423388.07 | N41: 18年1ヶ月 | O41: =O40+4400 -> 681800 | P41: =P40+(P52-P40)*1/12 -> 1.0297833 | Q41: =O41*P41 -> 702106.28
...

Sheet 退職金推移20年～40年
B3: 勤続年数 | C3: 積立金額 | D3: 支給率 | E3: 支給額 | F3: 勤続年数 | G3: 積立金額 | H3: 支給率 | I3: 支給額 | J3: 勤続年数 | K3: 積立金額 | L3: 支給率 | M3: 支給額 | N3: 勤続年数 | O3: 積立金額 | P3: 支給率 | Q3: 支給額
B4: 20年0ヶ月 | C4: 783000 | D4: 1.0362 | E4: =C4*D4 -> 811344.6 | F4: 25年0ヶ月 | G4: =C63+4400 -> 1047000 | H4: 1.0531 | I4: =G4*H4 -> 1102595.7 | J4: 30年0ヶ月 | K4: =G63+4400 -> 1311000 | L4: 1.0704 | M4: =K4*L4 -> 1403294.4 | N4: 35年0ヶ月 | O4: =K63+4400 -> 1575000 | P4: =L40+(L52-L40)*24/12 -> 1.0879 | Q4: =O4*P4 -> 1713442.5
B5: 20年1ヶ月 | C5: =C4+4400 -> 787400 | D5: =D4+(D16-D4)*1/12 -> 1.036475 | E5: =C5*D5 -> 816120.42 | F5: 25年1ヶ月 | G5: =G4+4400 -> 1051400 | H5: =H4+(H16-H4)*1/12 -> 1.0533833 | I5: =G5*H5 -> 1107527.2 | J5: 30年1ヶ月 | K5: =K4+4400 -> 1315400 | L5: =L4+(L16-L4)*1/12 -> 1.0706917 | M5: =K5*L5 -> 1408387.8 | N5: 35年1ヶ月 | O5: =O4+4400 -> 1579400 | Q5: =O5*P5 -> 0
B6: 20年2ヶ月 | C6: =C5+4400 -> 791800 | D6: =D4+(D16-D4)*2/12 -> 1.03675 | E6: =C6*D6 -> 820898.65 | F6: 25年2ヶ月 | G6: =G5+4400 -> 1055800 | H6: =H4+(H16-H4)*2/12 -> 1.0536667 | I6: =G6*H6 -> 1112461.3 | J6: 30年2ヶ月 | K6: =K5+4400 -> 1319800 | L6: =L4+(L16-L4)*2/12 -> 1.0709833 | M6: =K6*L6 -> 1413483.8 | N6: 35年2ヶ月 | O6: =O5+4400 -> 1583800 | Q6: =O6*P6 -> 0
B7: 20年3ヶ月 | C7: =C6+4400 -> 796200 | D7: =D4+(D16-D4)*3/12 -> 1.037025 | E7: =C7*D7 -> 825679.31 | F7: 25年3ヶ月 | G7: =G6+4400 -> 1060200 | H7: =H4+(H16-H4)*3/12 -> 1.05395 | I7: =G7*H7 -> 1117397.8 | J7: 30年3ヶ月 | K7: =K6+4400 -> 1324200 | L7: =L4+(L16-L4)*3/12 -> 1.071275 | M7: =K7*L7 -> 1418582.4 | N7: 35年3ヶ月 | O7: =O6+4400 -> 1588200 | Q7: =O7*P7 -> 0
B8: 20年4ヶ月 | C8: =C7+4400 -> 800600 | D8: =D4+(D16-D4)*4/12 -> 1.0373 | E8: =C8*D8 -> 830462.38 | F8: 25年4ヶ月 | G8: =G7+4400 -> 1064600 | H8: =H4+(H16-H4)*4/12 -> 1.0542333 | I8: =G8*H8 -> 1122336.8 | J8: 30年4ヶ月 | K8: =K7+4400 -> 1328600 | L8: =L4+(L16-L4)*4/12 -> 1.0715667 | M8: =K8*L8 -> 1423683.5 | N8: 35年4ヶ月 | O8: =O7+4400 -> 1592600 | Q8: =O8*P8 -> 0
B9: 20年5ヶ月 | C9: =C8+4400 -> 805000 | D9: =D4+(D16-D4)*5/12 -> 1.037575 | E9: =C9*D9 -> 835247.88 | F9: 25年5ヶ月 | G9: =G8+4400 -> 1069000 | H9: =H4+(H16-H4)*5/12 -> 1.0545167 | I9: =G9*H9 -> 1127278.3 | J9: 30年5ヶ月 | K9: =K8+4400 -> 1333000 | L9: =L4+(L16-L4)*5/12 -> 1.0718583 | M9: =K9*L9 -> 1428787.2 | N9: 35年5ヶ月 | O9: =O8+4400 -> 1597000 | Q9: =O9*P9 -> 0
B10: 20年6ヶ月 | C10: =C9+4400 -> 809400 | D10: =D4+(D16-D4)*6/12 -> 1.03785 | E10: =C10*D10 -> 840035.79 | F10: 25年6ヶ月 | G10: =G9+4400 -> 1073400 | H10: =H4+(H16-H4)*6/12 -> 1.0548 | I10: =G10*H10 -> 1132222.3 | J10: 30年6ヶ月 | K10: =K9+4400 -> 1337400 | L10: =L4+(L16-L4)*6/12 -> 1.07215 | M10: =K10*L10 -> 1433893.4 | N10: 35年6ヶ月 | O10: =O9+4400 -> 1601400 | Q10: =O10*P10 -> 0
B11: 20年7ヶ月 | C11: =C10+4400 -> 813800 | D11: =D4+(D16-D4)*7/12 -> 1.038125 | E11: =C11*D11 -> 844826.12 | F11: 25年7ヶ月 | G11: =G10+4400 -> 1077800 | H11: =H4+(H16-H4)*7/12 -> 1.0550833 | I11: =G11*H11 -> 1137168.8 | J11: 30年7ヶ月 | K11: =K10+4400 -> 1341800 | L11: =L4+(L16-L4)*7/12 -> 1.0724417 | M11: =K11*L11 -> 1439002.2 | N11: 35年7ヶ月 | O11: =O10+4400 -> 1605800 | Q11: =O11*P11 -> 0
B12: 20年8ヶ月 | C12: =C11+4400 -> 818200 | D12: =D4+(D16-D4)*8/12 -> 1.0384 | E12: =C12*D12 -> 849618.88 | F12: 25年8ヶ月 | G12: =G11+4400 -> 1082200 | H12: =H4+(H16-H4)*8/12 -> 1.0553667 | I12: =G12*H12 -> 1142117.8 | J12: 30年8ヶ月 | K12: =K11+4400 -> 1346200 | L12: =L4+(L16-L4)*8/12 -> 1.0727333 | M12: =K12*L12 -> 1444113.6 | N12: 35年8ヶ月 | O12: =O11+4400 -> 1610200 | Q12: =O12*P12 -> 0
B13: 20年9ヶ月 | C13: =C12+4400 -> 822600 | D13: =D4+(D16-D4)*9/12 -> 1.038675 | E13: =C13*D13 -> 854414.06 | F13: 25年9ヶ月 | G13: =G12+4400 -> 1086600 | H13: =H4+(H16-H4)*9/12 -> 1.05565 | I13: =G13*H13 -> 1147069.3 | J13: 30年9ヶ月 | K13: =K12+4400 -> 1350600 | L13: =L4+(L16-L4)*9/12 -> 1.073025 | M13: =K13*L13 -> 1449227.6 | N13: 35年9ヶ月 | O13: =O12+4400 -> 1614600 | Q13: =O13*P13 -> 0
B14: 20年10ヶ月 | C14: =C13+4400 -> 827000 | D14: =D4+(D16-D4)*10/12 -> 1.03895 | E14: =C14*D14 -> 859211.65 | F14: 25年10ヶ月 | G14: =G13+4400 -> 1091000 | H14: =H4+(H16-H4)*10/12 -> 1.0559333 | I14: =G14*H14 -> 1152023.3 | J14: 30年10ヶ月 | K14: =K13+4400 -> 1355000 | L14: =L4+(L16-L4)*10/12 -> 1.0733167 | M14: =K14*L14 -> 1454344.1 | N14: 35年10ヶ月 | O14: =O13+4400 -> 1619000 | Q14: =O14*P14 -> 0
B15: 20年11ヶ月 | C15: =C14+4400 -> 831400 | D15: =D4+(D16-D4)*11/12 -> 1.039225 | E15: =C15*D15 -> 864011.67 | F15: 25年11ヶ月 | G15: =G14+4400 -> 1095400 | H15: =H4+(H16-H4)*11/12 -> 1.0562167 | I15: =G15*H15 -> 1156979.7 | J15: 30年11ヶ月 | K15: =K14+4400 -> 1359400 | L15: =L4+(L16-L4)*11/12 -> 1.0736083 | M15: =K15*L15 -> 1459463.2 | N15: 35年11ヶ月 | O15: =O14+4400 -> 1623400 | Q15: =O15*P15 -> 0
B16: 21年0ヶ月 | C16: =C15+4400 -> 835800 | D16: 1.0395 | E16: =C16*D16 -> 868814.1 | F16: 26年0ヶ月 | G16: =G15+4400 -> 1099800 | H16: 1.0565 | I16: =G16*H16 -> 1161938.7 | J16: 31年0ヶ月 | K16: =K15+4400 -> 1363800 | L16: 1.0739 | M16: =K16*L16 -> 1464584.8 | N16: 36年0ヶ月 | O16: =O15+4400 -> 1627800 | P16: =L52+(P4-L52)*24/12 -> 1.0914 | Q16: =O16*P16 -> 1776580.9
B17: 21年1ヶ月 | C17: =C16+4400 -> 840200 | D17: =D16+(D28-D16)*1/12 -> 1.0397833 | E17: =C17*D17 -> 873625.96 | F17: 26年1ヶ月 | G17: =G16+4400 -> 1104200 | H17: =H16+(H28-H16)*1/12 -> 1.0567917 | I17: =G17*H17 -> 1166909.4 | J17: 31年1ヶ月 | K17: =K16+4400 -> 1368200 | L17: =L16+(L28-L16)*1/12 -> 1.0741917 | M17: =K17*L17 -> 1469709 | N17: 36年1ヶ月 | O17: =O16+4400 -> 1632200 | Q17: =O17*P17 -> 0
B18: 21年2ヶ月 | C18: =C17+4400 -> 844600 | D18: =D16+(D28-D16)*2/12 -> 1.0400667 | E18: =C18*D18 -> 878440.31 | F18: 26年2ヶ月 | G18: =G17+4400 -> 1108600 | H18: =H16+(H28-H16)*2/12 -> 1.0570833 | I18: =G18*H18 -> 1171882.6 | J18: 31年2ヶ月 | K18: =K17+4400 -> 1372600 | L18: =L16+(L28-L16)*2/12 -> 1.0744833 | M18: =K18*L18 -> 1474835.8 | N18: 36年2ヶ月 | O18: =O17+4400 -> 1636600 | Q18: =O18*P18 -> 0
B19: 21年3ヶ月 | C19: =C18+4400 -> 849000 | D19: =D16+(D28-D16)*3/12 -> 1.04035 | E19: =C19*D19 -> 883257.15 | F19: 26年3ヶ月 | G19: =G18+4400 -> 1113000 | H19: =H16+(H28-H16)*3/12 -> 1.057375 | I19: =G19*H19 -> 1176858.4 | J19: 31年3ヶ月 | K19: =K18+4400 -> 1377000 | L19: =L16+(L28-L16)*3/12 -> 1.074775 | M19: =K19*L19 -> 1479965.2 | N19: 36年3ヶ月 | O19: =O18+4400 -> 1641000 | Q19: =O19*P19 -> 0
B20: 21年4ヶ月 | C20: =C19+4400 -> 853400 | D20: =D16+(D28-D16)*4/12 -> 1.0406333 | E20: =C20*D20 -> 888076.49 | F20: 26年4ヶ月 | G20: =G19+4400 -> 1117400 | H20: =H16+(H28-H16)*4/12 -> 1.0576667 | I20: =G20*H20 -> 1181836.7 | J20: 31年4ヶ月 | K20: =K19+4400 -> 1381400 | L20: =L16+(L28-L16)*4/12 -> 1.0750667 | M20: =K20*L20 -> 1485097.1 | N20: 36年4ヶ月 | O20: =O19+4400 -> 1645400 | Q20: =O20*P20 -> 0
B21: 21年5ヶ月 | C21: =C20+4400 -> 857800 | D21: =D16+(D28-D16)*5/12 -> 1.0409167 | E21: =C21*D21 -> 892898.32 | F21: 26年5ヶ月 | G21: =G20+4400 -> 1121800 | H21: =H16+(H28-H16)*5/12 -> 1.0579583 | I21: =G21*H21 -> 1186817.7 | J21: 31年5ヶ月 | K21: =K20+4400 -> 1385800 | L21: =L16+(L28-L16)*5/12 -> 1.0753583 | M21: =K21*L21 -> 1490231.6 | N21: 36年5ヶ月 | O21: =O20+4400 -> 1649800 | Q21: =O21*P21 -> 0
B22: 21年6ヶ月 | C22: =C21+4400 -> 862200 | D22: =D16+(D28-D16)*6/12 -> 1.0412 | E22: =C22*D22 -> 897722.64 | F22: 26年6ヶ月 | G22: =G21+4400 -> 1126200 | H22: =H16+(H28-H16)*6/12 -> 1.05825 | I22: =G22*H22 -> 1191801.2 | J22: 31年6ヶ月 | K22: =K21+4400 -> 1390200 | L22: =L16+(L28-L16)*6/12 -> 1.07565 | M22: =K22*L22 -> 1495368.6 | N22: 36年6ヶ月 | O22: =O21+4400 -> 1654200 | Q22: =O22*P22 -> 0
B23: 21年7ヶ月 | C23: =C22+4400 -> 866600 | D23: =D16+(D28-D16)*7/12 -> 1.0414833 | E23: =C23*D23 -> 902549.46 | F23: 26年7ヶ月 | G23: =G22+4400 -> 1130600 | H23: =H16+(H28-H16)*7/12 -> 1.0585417 | I23: =G23*H23 -> 1196787.2 | J23: 31年7ヶ月 | K23: =K22+4400 -> 1394600 | L23: =L16+(L28-L16)*7/12 -> 1.0759417 | M23: =K23*L23 -> 1500508.2 | N23: 36年7ヶ月 | O23: =O22+4400 -> 1658600 | Q23: =O23*P23 -> 0
B24: 21年8ヶ月 | C24: =C23+4400 -> 871000 | D24: =D16+(D28-D16)*8/12 -> 1.0417667 | E24: =C24*D24 -> 907378.77 | F24: 26年8ヶ月 | G24: =G23+4400 -> 1135000 | H24: =H16+(H28-H16)*8/12 -> 1.0588333 | I24: =G24*H24 -> 1201775.8 | J24: 31年8ヶ月 | K24: =K23+4400 -> 1399000 | L24: =L16+(L28-L16)*8/12 -> 1.0762333 | M24: =K24*L24 -> 1505650.4 | N24: 36年8ヶ月 | O24: =O23+4400 -> 1663000 | Q24: =O24*P24 -> 0
B25: 21年9ヶ月 | C25: =C24+4400 -> 875400 | D25: =D16+(D28-D16)*9/12 -> 1.04205 | E25: =C25*D25 -> 912210.57 | F25: 26年9ヶ月 | G25: =G24+4400 -> 1139400 | H25: =H16+(H28-H16)*9/12 -> 1.059125 | I25: =G25*H25 -> 1206767 | J25: 31年9ヶ月 | K25: =K24+4400 -> 1403400 | L25: =L16+(L28-L16)*9/12 -> 1.076525 | M25: =K25*L25 -> 1510795.2 | N25: 36年9ヶ月 | O25: =O24+4400 -> 1667400 | Q25: =O25*P25 -> 0
B26: 21年10ヶ月 | C26: =C25+4400 -> 879800 | D26: =D16+(D28-D16)*10/12 -> 1.0423333 | E26: =C26*D26 -> 917044.87 | F26: 26年10ヶ月 | G26: =G25+4400 -> 1143800 | H26: =H16+(H28-H16)*10/12 -> 1.0594167 | I26: =G26*H26 -> 1211760.8 | J26: 31年10ヶ月 | K26: =K25+4400 -> 1407800 | L26: =L16+(L28-L16)*10/12 -> 1.0768167 | M26: =K26*L26 -> 1515942.5 | N26: 36年10ヶ月 | O26: =O25+4400 -> 1671800 | Q26: =O26*P26 -> 0
B27: 21年11ヶ月 | C27: =C26+4400 -> 884200 | D27: =D16+(D28-D16)*11/12 -> 1.0426167 | E27: =C27*D27 -> 921881.66 | F27: 26年11ヶ月 | G27: =G26+4400 -> 1148200 | H27: =H16+(H28-H16)*11/12 -> 1.0597083 | I27: =G27*H27 -> 1216757.1 | J27: 31年11ヶ月 | K27: =K26+4400 -> 1412200 | L27: =L16+(L28-L16)*11/12 -> 1.0771083 | M27: =K27*L27 -> 1521092.4 | N27: 36年11ヶ月 | O27: =O26+4400 -> 1676200 | Q27: =O27*P27 -> 0
